Workbook

Sheet Result02
A1: Feature_Selection | B1: Model | C1: train_auc | D1: train_pr_auc | E1: train_precision | F1: train_recall | G1: train_f1 | H1: train_accuracy | I1: test_auc | J1: test_pr_auc | K1: test_precision | L1: test_recall | M1: test_f1 | N1: test_accuracy
A2: Full_Set_Baseline | B2: XGBoost | C2: 0.9380 | D2: 0.7426 | E2: 0.8552 | F2: 0.695 | G2: 0.7667 | H2: 0.9994 | I2: 0.909 | J2: 0.6729 | K2: 0.8285 | L2: 0.669 | M2: 0.7402 | N2: 0.9993
A3: Lasso (a=1e-6) | B3: XGBoost | C3: 0.9363 | D3: 0.7349 | E3: 0.8508 | F3: 0.6973 | G3: 0.7664 | H3: 0.9994 | I3: 0.913 | J3: 0.686 | K3: 0.8181 | L3: 0.6793 | M3: 0.7422 | N3: 0.9993
A4: Ridge (a=1e6) | B4: XGBoost | C4: 0.8963 | D4: 0.6320 | E4: 0.7962 | F4: 0.6134 | G4: 0.6928 | H4: 0.9992 | I4: 0.9067 | J4: 0.6805 | K4: 0.8326 | L4: 0.648 | M4: 0.7288 | N4: 0.9993
A5: Ridge (a=1e3) | B5: XGBoost | C5: 0.8987 | D5: 0.3944 | E5: 0.675 | F5: 0.3567 | G5: 0.4666 | H5: 0.9988 | I5: 0.8276 | J5: 0.3317 | K5: 0.6167 | L5: 0.3058 | M5: 0.4088 | N5: 0.9987
A6: Ridge (a=1e2) | B6: XGBoost | C6: 0.8987 | D6: 0.3944 | E6: 0.675 | F6: 0.3567 | G6: 0.4666 | H6: 0.9988 | I6: 0.8276 | J6: 0.3317 | K6: 0.6167 | L6: 0.3058 | M6: 0.4088 | N6: 0.9987
A7: Ridge (a=1e4) | B7: XGBoost | C7: 0.8820 | D7: 0.3687 | E7: 0.6425 | F7: 0.3509 | G7: 0.4539 | H7: 0.9987 | I7: 0.8579 | J7: 0.346 | K7: 0.5801 | L7: 0.3385 | M7: 0.4275 | N7: 0.9986
A8: Ridge (a=1e5) | B8: XGBoost | C8: 0.8914 | D8: 0.3414 | E8: 0.6281 | F8: 0.34 | G8: 0.4406 | H8: 0.9987 | I8: 0.9056 | J8: 0.3809 | K8: 0.6627 | L8: 0.3212 | M8: 0.4327 | N8: 0.9987
A9: XGBoost_Top10 | B9: XGBoost | C9: 0.8704 | D9: 0.3204 | E9: 0.6104 | F9: 0.3184 | G9: 0.4183 | H9: 0.9987 | I9: 0.855 | J9: 0.322 | K9: 0.6342 | L9: 0.2865 | M9: 0.3947 | N9: 0.9987
A10: Lasso (a=1e-5) | B10: XGBoost | C10: 0.8597 | D10: 0.3043 | E10: 0.6035 | F10: 0.299 | G10: 0.3996 | H10: 0.9987 | I10: 0.8222 | J10: 0.2509 | K10: 0.5858 | L10: 0.268 | M10: 0.3678 | N10: 0.9986
A11: Lasso (a=1e-4) | B11: XGBoost | C11: 0.9286 | D11: 0.2481 | E11: 0.8412 | F11: 0.2155 | G11: 0.3429 | H11: 0.9988 | I11: 0.7242 | J11: 0.0116 | K11: 0 | L11: 0 | M11: 0 | N11: 0.9966
A12: Lasso (a=1e-6) | B12: LDA | C12: 0.8666 | D12: 0.0270 | E12: 0.0507 | F12: 0.1436 | G12: 0.0749 | H12: 0.9947 | I12: 0.8618 | J12: 0.0249 | K12: 0.0502 | L12: 0.141 | M12: 0.0741 | N12: 0.9947
A13: Ridge (a=1e4) | B13: LDA | C13: 0.8674 | D13: 0.0267 | E13: 0.0504 | F13: 0.1421 | G13: 0.0744 | H13: 0.9947 | I13: 0.8619 | J13: 0.0246 | K13: 0.0495 | L13: 0.139 | M13: 0.073 | N13: 0.9947
... A40: XGBoost_Top10 | B40: LogisticRegression | C40: 0.8763 | D40: 0.0081 | E40: 0 | F40: 0 | G40: 0 | H40: 0.9985 | I40: 0.8749 | J40: 0.0081 | K40: 0 | L40: 0 | M40: 0 | N40: 0.9985

Sheet 結果
B2: =_xlfn.CONCAT("總方法數：", COUNTA(使用方法!A:A), "x", COUNTA(使用方法!B:B), " = ", COUNTA(使用方法!A:A)*COUNTA(使用方法!B:B)) -> 總方法數：4x10 = 40 | D2: Result02
B3: ML | D3: Feature Selection | F3: {=TRANSPOSE(_xlfn._xlws.FILTER(使用方法!C:C, 使用方法!C:C<>0))} -> train_precision | G3: train_recall | H3: train_f1 | I3: train_auc | J3: train_pr_auc | K3: train_accuracy | L3: test_precision | M3: test_recall | N3: test_f1 | O3: test_auc | P3: test_pr_auc | Q3: test_accuracy
B4: {=IFERROR( IF( MOD(ROW()-ROW($B$4), COUNTA(使用方法!$B:$B)) = 0, IF(INDEX(使用方法!$A:$A, INT((ROW()-ROW($B$4))/COUNTA(使用方法!$B:$B))+1) = "", "", INDEX(使用方法!$A:$A, INT((ROW()-ROW($B$4))/COUNTA(使用方法!$B:$B))+1) ), "" ), "")} -> LogisticRegression | C4: =IF(B4<>"", B4, C3) -> LogisticRegression | D4: {=_xlfn.LET( _xlpm.data, _xlfn._xlws.FILTER(使用方法!B:B, 使用方法!B:B<>""), _xlpm.n, COUNTA(使用方法!A:A), _xlpm.totalRows, ROWS(_xlpm.data) * _xlpm.n, _xlpm.seq, _xlfn.SEQUENCE(_xlpm.totalRows, 1, 0, 1), INDEX(_xlpm.data, MOD(_xlpm.seq, ROWS(_xlpm.data)) + 1) )} -> Full_Set_Baseline | F4: {=_xlfn.LET( _xlpm.sheet, $D$2, _xlpm.rowMatch, MATCH( TRIM($D4)&"|"&TRIM($C4), TRIM(INDIRECT(_xlpm.sheet & "!A2:A45")) & "|" & TRIM(INDIRECT(_xlpm.sheet & "!B2:B45")), 0 ), _xlpm.colMatch, MATCH( TRIM(F$3), TRIM(INDIRECT(_xlpm.sheet & "!C1:M1")), 0 ), _xlpm.val, IFERROR(INDEX(INDIRECT(_xlpm.sheet & "!C2:M100"), _xlpm.rowMatch, _xlpm.colMatch), ""), IF(_xlpm.val="", "", _xlpm.val) )} -> 0 | G4: {=_xlfn.LET( _xlpm.sheet, $D$2, _xlpm.rowMatch, MATCH( TRIM($D4)&"|"&TRIM($C4), TRIM(INDIRECT(_xlpm.sheet & "!A2:A45")) & "|" & TRIM(INDIRECT(_xlpm.sheet & "!B2:B45")), 0 ), _xlpm.colMatch, MATCH( TRIM(G$3), TRIM(INDIRECT(_xlpm.sheet & "!C1:M1")), 0 ), _xlpm.val, IFERROR(INDEX(INDIRECT(_xlpm.sheet & "!C2:M100"), _xlpm.rowMatch, _xlpm.colMatch), ""), IF(_xlpm.val="", "", _xlpm.val) )} -> 0 | H4: {=_xlfn.LET( _xlpm.sheet, $D$2, _xlpm.rowMatch, MATCH( TRIM($D4)&"|"&TRIM($C4), TRIM(INDIRECT(_xlpm.sheet & "!A2:A45")) & "|" & TRIM(INDIRECT(_xlpm.sheet & "!B2:B45")), 0 ), _xlpm.colMatch, MATCH( TRIM(H$3), TRIM(INDIRECT(_xlpm.sheet & "!C1:M1")), 0 ), _xlpm.val, IFERROR(INDEX(INDIRECT(_xlpm.sheet & "!C2:M100"), _xlpm.rowMatch, _xlpm.colMatch), ""), IF(_xlpm.val="", "", _xlpm.val) )} -> 0 | I4: {=_xlfn.LET( _xlpm.sheet, $D$2, _xlpm.rowMatch, MATCH( TRIM($D4)&"|"&TRIM($C4), TRIM(INDIRECT(_xlpm.sheet & "!A2:A45")) & "|" & TRIM(INDIRECT(_xlpm.sheet & "!B2:B45")), 0 ), _xlpm.colMatch, MATCH( TRIM(I$3), TRIM(INDIRECT(_xlpm.sheet & "!C1:M1")), 0 ), _xlpm.val, IFERROR(INDEX(INDIRECT(_xlpm.sheet & "!C2:M100"), _xlpm.rowMatch, _xlpm.colMatch), ""), IF(_xlpm.val="", "", _xlpm.val) )} -> 0.8698 | J4: {=_xlfn.LET( _xlpm.sheet, $D$2, _xlpm.rowMatch, MATCH( TRIM($D4)&"|"&TRIM($C4), TRIM(INDIRECT(_xlpm.sheet & "!A2:A45")) & "|" & TRIM(INDIRECT(_xlpm.sheet & "!B2:B45")), 0 ), _xlpm.colMatch, MATCH( TRIM(J$3), TRIM(INDIRECT(_xlpm.sheet & "!C1:M1")), 0 ), _xlpm.val, IFERROR(INDEX(INDIRECT(_xlpm.sheet & "!C2:M100"), _xlpm.rowMatch, _xlpm.colMatch), ""), IF(_xlpm.val="", "", _xlpm.val) )} -> 0.0138 | K4: {=_xlfn.LET( _xlpm.sheet, $D$2, _xlpm.rowMatch, MATCH( TRIM($D4)&"|"&TRIM($C4), TRIM(INDIRECT(_xlpm.sheet & "!A2:A45")) & "|" & TRIM(INDIRECT(_xlpm.sheet & "!B2:B45")), 0 ), _xlpm.colMatch, MATCH( TRIM(K$3), TRIM(INDIRECT(_xlpm.sheet & "!C1:M1")), 0 ), _xlpm.val, IFERROR(INDEX(INDIRECT(_xlpm.sheet & "!C2:M100"), _xlpm.rowMatch, _xlpm.colMatch), ""), IF(_xlpm.val="", "", _xlpm.val) )} -> 0.9985 | L4: {=_xlfn.LET( _xlpm.sheet, $D$2, _xlpm.rowMatch, MATCH( TRIM($D4)&"|"&TRIM($C4), TRIM(INDIRECT(_xlpm.sheet & "!A2:A45")) & "|" & TRIM(INDIRECT(_xlpm.sheet & "!B2:B45")), 0 ), _xlpm.colMatch, MATCH( TRIM(L$3), TRIM(INDIRECT(_xlpm.sheet & "!C1:M1")), 0 ), _xlpm.val, IFERROR(INDEX(INDIRECT(_xlpm.sheet & "!C2:M100"), _xlpm.rowMatch, _xlpm.colMatch), ""), IF(_xlpm.val="", "", _xlpm.val) )} -> 0 | M4: {=_xlfn.LET( _xlpm.sheet, $D$2, _xlpm.rowMatch, MATCH( TRIM($D4)&"|"&TRIM($C4), TRIM(INDIRECT(_xlpm.sheet & "!A2:A45")) & "|" & TRIM(INDIRECT(_xlpm.sheet & "!B2:B45")), 0 ), _xlpm.colMatch, MATCH( TRIM(M$3), TRIM(INDIRECT(_xlpm.sheet & "!C1:M1")), 0 ), _xlpm.val, IFERROR(INDEX(INDIRECT(_xlpm.sheet & "!C2:M100"), _xlpm.rowMatch, _xlpm.colMatch), ""), IF(_xlpm.val="", "", _xlpm.val) )} -> 0 | ... P4: {=_xlfn.LET( _xlpm.sheet, $D$2, _xlpm.rowMatch, MATCH( TRIM($D4)&"|"&TRIM($C4), TRIM(INDIRECT(_xlpm.sheet & "!A2:A45")) & "|" & TRIM(INDIRECT(_xlpm.sheet & "!B2:B45")), 0 ), _xlpm.colMatch, MATCH( TRIM(P$3), TRIM(INDIRECT(_xlpm.sheet & "!C1:M1")), 0 ), _xlpm.val, IFERROR(INDEX(INDIRECT(_xlpm.sheet & "!C2:M100"), _xlpm.rowMatch, _xlpm.colMatch), ""), IF(_xlpm.val="", "", _xlpm.val) )} -> 0.0141 | Q4: {=_xlfn.LET( _xlpm.sheet, $D$2, _xlpm.rowMatch, MATCH( TRIM($D4)&"|"&TRIM($C4), TRIM(INDIRECT(_xlpm.sheet & "!A2:A45")) & "|" & TRIM(INDIRECT(_xlpm.sheet & "!B2:B45")), 0 ), _xlpm.colMatch, MATCH( TRIM(Q$3), TRIM(INDIRECT(_xlpm.sheet & "!C1:N1")), 0 ), _xlpm.val, IFERROR(INDEX(INDIRECT(_xlpm.sheet & "!C2:N100"), _xlpm.rowMatch, _xlpm.colMatch), ""), IF(_xlpm.val="", "", _xlpm.val) )} -> 0.9985
B5: {=IFERROR( IF( MOD(ROW()-ROW($B$4), COUNTA(使用方法!$B:$B)) = 0, IF(INDEX(使用方法!$A:$A, INT((ROW()-ROW($B$4))/COUNTA(使用方法!$B:$B))+1) = "", "", INDEX(使用方法!$A:$A, INT((ROW()-ROW($B$4))/COUNTA(使用方法!$B:$B))+1) ), "" ), "")} | C5: =IF(B5<>"", B5, C4) -> LogisticRegression | D5: Lasso (a=1e-4) | F5: {=_xlfn.LET( _xlpm.sheet, $D$2, _xlpm.rowMatch, MATCH( TRIM($D5)&"|"&TRIM($C5), TRIM(INDIRECT(_xlpm.sheet & "!A2:A45")) & "|" & TRIM(INDIRECT(_xlpm.sheet & "!B2:B45")), 0 ), _xlpm.colMatch, MATCH( TRIM(F$3), TRIM(INDIRECT(_xlpm.sheet & "!C1:M1")), 0 ), _xlpm.val, IFERROR(INDEX(INDIRECT(_xlpm.sheet & "!C2:M100"), _xlpm.rowMatch, _xlpm.colMatch), ""), IF(_xlpm.val="", "", _xlpm.val) )} -> 0 | G5: {=_xlfn.LET( _xlpm.sheet, $D$2, _xlpm.rowMatch, MATCH( TRIM($D5)&"|"&TRIM($C5), TRIM(INDIRECT(_xlpm.sheet & "!A2:A45")) & "|" & TRIM(INDIRECT(_xlpm.sheet & "!B2:B45")), 0 ), _xlpm.colMatch, MATCH( TRIM(G$3), TRIM(INDIRECT(_xlpm.sheet & "!C1:M1")), 0 ), _xlpm.val, IFERROR(INDEX(INDIRECT(_xlpm.sheet & "!C2:M100"), _xlpm.rowMatch, _xlpm.colMatch), ""), IF(_xlpm.val="", "", _xlpm.val) )} -> 0 | H5: {=_xlfn.LET( _xlpm.sheet, $D$2, _xlpm.rowMatch, MATCH( TRIM($D5)&"|"&TRIM($C5), TRIM(INDIRECT(_xlpm.sheet & "!A2:A45")) & "|" & TRIM(INDIRECT(_xlpm.sheet & "!B2:B45")), 0 ), _xlpm.colMatch, MATCH( TRIM(H$3), TRIM(INDIRECT(_xlpm.sheet & "!C1:M1")), 0 ), _xlpm.val, IFERROR(INDEX(INDIRECT(_xlpm.sheet & "!C2:M100"), _xlpm.rowMatch, _xlpm.colMatch), ""), IF(_xlpm.val="", "", _xlpm.val) )} -> 0 | I5: {=_xlfn.LET( _xlpm.sheet, $D$2, _xlpm.rowMatch, MATCH( TRIM($D5)&"|"&TRIM($C5), TRIM(INDIRECT(_xlpm.sheet & "!A2:A45")) & "|" & TRIM(INDIRECT(_xlpm.sheet & "!B2:B45")), 0 ), _xlpm.colMatch, MATCH( TRIM(I$3), TRIM(INDIRECT(_xlpm.sheet & "!C1:M1")), 0 ), _xlpm.val, IFERROR(INDEX(INDIRECT(_xlpm.sheet & "!C2:M100"), _xlpm.rowMatch, _xlpm.colMatch), ""), IF(_xlpm.val="", "", _xlpm.val) )} -> 0.8736 | J5: {=_xlfn.LET( _xlpm.sheet, $D$2, _xlpm.rowMatch, MATCH( TRIM($D5)&"|"&TRIM($C5), TRIM(INDIRECT(_xlpm.sheet & "!A2:A45")) & "|" & TRIM(INDIRECT(_xlpm.sheet & "!B2:B45")), 0 ), _xlpm.colMatch, MATCH( TRIM(J$3), TRIM(INDIRECT(_xlpm.sheet & "!C1:M1")), 0 ), _xlpm.val, IFERROR(INDEX(INDIRECT(_xlpm.sheet & "!C2:M100"), _xlpm.rowMatch, _xlpm.colMatch), ""), IF(_xlpm.val="", "", _xlpm.val) )} -> 0.0132 | K5: {=_xlfn.LET( _xlpm.sheet, $D$2, _xlpm.rowMatch, MATCH( TRIM($D5)&"|"&TRIM($C5), TRIM(INDIRECT(_xlpm.sheet & "!A2:A45")) & "|" & TRIM(INDIRECT(_xlpm.sheet & "!B2:B45")), 0 ), _xlpm.colMatch, MATCH( TRIM(K$3), TRIM(INDIRECT(_xlpm.sheet & "!C1:M1")), 0 ), _xlpm.val, IFERROR(INDEX(INDIRECT(_xlpm.sheet & "!C2:M100"), _xlpm.rowMatch, _xlpm.colMatch), ""), IF(_xlpm.val="", "", _xlpm.val) )} -> 0.9985 | L5: {=_xlfn.LET( _xlpm.sheet, $D$2, _xlpm.rowMatch, MATCH( TRIM($D5)&"|"&TRIM($C5), TRIM(INDIRECT(_xlpm.sheet & "!A2:A45")) & "|" & TRIM(INDIRECT(_xlpm.sheet & "!B2:B45")), 0 ), _xlpm.colMatch, MATCH( TRIM(L$3), TRIM(INDIRECT(_xlpm.sheet & "!C1:M1")), 0 ), _xlpm.val, IFERROR(INDEX(INDIRECT(_xlpm.sheet & "!C2:M100"), _xlpm.rowMatch, _xlpm.colMatch), ""), IF(_xlpm.val="", "", _xlpm.val) )} -> 0 | M5: {=_xlfn.LET( _xlpm.sheet, $D$2, _xlpm.rowMatch, MATCH( TRIM($D5)&"|"&TRIM($C5), TRIM(INDIRECT(_xlpm.sheet & "!A2:A45")) & "|" & TRIM(INDIRECT(_xlpm.sheet & "!B2:B45")), 0 ), _xlpm.colMatch, MATCH( TRIM(M$3), TRIM(INDIRECT(_xlpm.sheet & "!C1:M1")), 0 ), _xlpm.val, IFERROR(INDEX(INDIRECT(_xlpm.sheet & "!C2:M100"), _xlpm.rowMatch, _xlpm.colMatch), ""), IF(_xlpm.val="", "", _xlpm.val) )} -> 0 | ... P5: {=_xlfn.LET( _xlpm.sheet, $D$2, _xlpm.rowMatch, MATCH( TRIM($D5)&"|"&TRIM($C5), TRIM(INDIRECT(_xlpm.sheet & "!A2:A45")) & "|" & TRIM(INDIRECT(_xlpm.sheet & "!B2:B45")), 0 ), _xlpm.colMatch, MATCH( TRIM(P$3), TRIM(INDIRECT(_xlpm.sheet & "!C1:M1")), 0 ), _xlpm.val, IFERROR(INDEX(INDIRECT(_xlpm.sheet & "!C2:M100"), _xlpm.rowMatch, _xlpm.colMatch), ""), IF(_xlpm.val="", "", _xlpm.val) )} -> 0.0135 | Q5: {=_xlfn.LET( _xlpm.sheet, $D$2, _xlpm.rowMatch, MATCH( TRIM($D5)&"|"&TRIM($C5), TRIM(INDIRECT(_xlpm.sheet & "!A2:A45")) & "|" & TRIM(INDIRECT(_xlpm.sheet & "!B2:B45")), 0 ), _xlpm.colMatch, MATCH( TRIM(Q$3), TRIM(INDIRECT(_xlpm.sheet & "!C1:N1")), 0 ), _xlpm.val, IFERROR(INDEX(INDIRECT(_xlpm.sheet & "!C2:N100"), _xlpm.rowMatch, _xlpm.colMatch), ""), IF(_xlpm.val="", "", _xlpm.val) )} -> 0.9985
B6: {=IFERROR( IF( MOD(ROW()-ROW($B$4), COUNTA(使用方法!$B:$B)) = 0, IF(INDEX(使用方法!$A:$A, INT((ROW()-ROW($B$4))/COUNTA(使用方法!$B:$B))+1) = "", "", INDEX(使用方法!$A:$A, INT((ROW()-ROW($B$4))/COUNTA(使用方法!$B:$B))+1) ), "" ), "")} | C6: =IF(B6<>"", B6, C5) -> LogisticRegression | D6: Lasso (a=1e-5) | F6: {=_xlfn.LET( _xlpm.sheet, $D$2, _xlpm.rowMatch, MATCH( TRIM($D6)&"|"&TRIM($C6), TRIM(INDIRECT(_xlpm.sheet & "!A2:A45")) & "|" & TRIM(INDIRECT(_xlpm.sheet & "!B2:B45")), 0 ), _xlpm.colMatch, MATCH( TRIM(F$3), TRIM(INDIRECT(_xlpm.sheet & "!C1:M1")), 0 ), _xlpm.val, IFERROR(INDEX(INDIRECT(_xlpm.sheet & "!C2:M100"), _xlpm.rowMatch, _xlpm.colMatch), ""), IF(_xlpm.val="", "", _xlpm.val) )} -> 0 | G6: {=_xlfn.LET( _xlpm.sheet, $D$2, _xlpm.rowMatch, MATCH( TRIM($D6)&"|"&TRIM($C6), TRIM(INDIRECT(_xlpm.sheet & "!A2:A45")) & "|" & TRIM(INDIRECT(_xlpm.sheet & "!B2:B45")), 0 ), _xlpm.colMatch, MATCH( TRIM(G$3), TRIM(INDIRECT(_xlpm.sheet & "!C1:M1")), 0 ), _xlpm.val, IFERROR(INDEX(INDIRECT(_xlpm.sheet & "!C2:M100"), _xlpm.rowMatch, _xlpm.colMatch), ""), IF(_xlpm.val="", "", _xlpm.val) )} -> 0 | H6: {=_xlfn.LET( _xlpm.sheet, $D$2, _xlpm.rowMatch, MATCH( TRIM($D6)&"|"&TRIM($C6), TRIM(INDIRECT(_xlpm.sheet & "!A2:A45")) & "|" & TRIM(INDIRECT(_xlpm.sheet & "!B2:B45")), 0 ), _xlpm.colMatch, MATCH( TRIM(H$3), TRIM(INDIRECT(_xlpm.sheet & "!C1:M1")), 0 ), _xlpm.val, IFERROR(INDEX(INDIRECT(_xlpm.sheet & "!C2:M100"), _xlpm.rowMatch, _xlpm.colMatch), ""), IF(_xlpm.val="", "", _xlpm.val) )} -> 0 | I6: {=_xlfn.LET( _xlpm.sheet, $D$2, _xlpm.rowMatch, MATCH( TRIM($D6)&"|"&TRIM($C6), TRIM(INDIRECT(_xlpm.sheet & "!A2:A45")) & "|" & TRIM(INDIRECT(_xlpm.sheet & "!B2:B45")), 0 ), _xlpm.colMatch, MATCH( TRIM(I$3), TRIM(INDIRECT(_xlpm.sheet & "!C1:M1")), 0 ), _xlpm.val, IFERROR(INDEX(INDIRECT(_xlpm.sheet & "!C2:M100"), _xlpm.rowMatch, _xlpm.colMatch), ""), IF(_xlpm.val="", "", _xlpm.val) )} -> 0.8891 | J6: {=_xlfn.LET( _xlpm.sheet, $D$2, _xlpm.rowMatch, MATCH( TRIM($D6)&"|"&TRIM($C6), TRIM(INDIRECT(_xlpm.sheet & "!A2:A45")) & "|" & TRIM(INDIRECT(_xlpm.sheet & "!B2:B45")), 0 ), _xlpm.colMatch, MATCH( TRIM(J$3), TRIM(INDIRECT(_xlpm.sheet & "!C1:M1")), 0 ), _xlpm.val, IFERROR(INDEX(INDIRECT(_xlpm.sheet & "!C2:M100"), _xlpm.rowMatch, _xlpm.colMatch), ""), IF(_xlpm.val="", "", _xlpm.val) )} -> 0.0167 | K6: {=_xlfn.LET( _xlpm.sheet, $D$2, _xlpm.rowMatch, MATCH( TRIM($D6)&"|"&TRIM($C6), TRIM(INDIRECT(_xlpm.sheet & "!A2:A45")) & "|" & TRIM(INDIRECT(_xlpm.sheet & "!B2:B45")), 0 ), _xlpm.colMatch, MATCH( TRIM(K$3), TRIM(INDIRECT(_xlpm.sheet & "!C1:M1")), 0 ), _xlpm.val, IFERROR(INDEX(INDIRECT(_xlpm.sheet & "!C2:M100"), _xlpm.rowMatch, _xlpm.colMatch), ""), IF(_xlpm.val="", "", _xlpm.val) )} -> 0.9985 | L6: {=_xlfn.LET( _xlpm.sheet, $D$2, _xlpm.rowMatch, MATCH( TRIM($D6)&"|"&TRIM($C6), TRIM(INDIRECT(_xlpm.sheet & "!A2:A45")) & "|" & TRIM(INDIRECT(_xlpm.sheet & "!B2:B45")), 0 ), _xlpm.colMatch, MATCH( TRIM(L$3), TRIM(INDIRECT(_xlpm.sheet & "!C1:M1")), 0 ), _xlpm.val, IFERROR(INDEX(INDIRECT(_xlpm.sheet & "!C2:M100"), _xlpm.rowMatch, _xlpm.colMatch), ""), IF(_xlpm.val="", "", _xlpm.val) )} -> 0 | M6: {=_xlfn.LET( _xlpm.sheet, $D$2, _xlpm.rowMatch, MATCH( TRIM($D6)&"|"&TRIM($C6), TRIM(INDIRECT(_xlpm.sheet & "!A2:A45")) & "|" & TRIM(INDIRECT(_xlpm.sheet & "!B2:B45")), 0 ), _xlpm.colMatch, MATCH( TRIM(M$3), TRIM(INDIRECT(_xlpm.sheet & "!C1:M1")), 0 ), _xlpm.val, IFERROR(INDEX(INDIRECT(_xlpm.sheet & "!C2:M100"), _xlpm.rowMatch, _xlpm.colMatch), ""), IF(_xlpm.val="", "", _xlpm.val) )} -> 0 | ... P6: {=_xlfn.LET( _xlpm.sheet, $D$2, _xlpm.rowMatch, MATCH( TRIM($D6)&"|"&TRIM($C6), TRIM(INDIRECT(_xlpm.sheet & "!A2:A45")) & "|" & TRIM(INDIRECT(_xlpm.sheet & "!B2:B45")), 0 ), _xlpm.colMatch, MATCH( TRIM(P$3), TRIM(INDIRECT(_xlpm.sheet & "!C1:M1")), 0 ), _xlpm.val, IFERROR(INDEX(INDIRECT(_xlpm.sheet & "!C2:M100"), _xlpm.rowMatch, _xlpm.colMatch), ""), IF(_xlpm.val="", "", _xlpm.val) )} -> 0.0174 | Q6: {=_xlfn.LET( _xlpm.sheet, $D$2, _xlpm.rowMatch, MATCH( TRIM($D6)&"|"&TRIM($C6), TRIM(INDIRECT(_xlpm.sheet & "!A2:A45")) & "|" & TRIM(INDIRECT(_xlpm.sheet & "!B2:B45")), 0 ), _xlpm.colMatch, MATCH( TRIM(Q$3), TRIM(INDIRECT(_xlpm.sheet & "!C1:N1")), 0 ), _xlpm.val, IFERROR(INDEX(INDIRECT(_xlpm.sheet & "!C2:N100"), _xlpm.rowMatch, _xlpm.colMatch), ""), IF(_xlpm.val="", "", _xlpm.val) )} -> 0.9985
B7: {=IFERROR( IF( MOD(ROW()-ROW($B$4), COUNTA(使用方法!$B:$B)) = 0, IF(INDEX(使用方法!$A:$A, INT((ROW()-ROW($B$4))/COUNTA(使用方法!$B:$B))+1) = "", "", INDEX(使用方法!$A:$A, INT((ROW()-ROW($B$4))/COUNTA(使用方法!$B:$B))+1) ), "" ), "")} | C7: =IF(B7<>"", B7, C6) -> LogisticRegression | D7: Lasso (a=1e-6) | F7: {=_xlfn.LET( _xlpm.sheet, $D$2, _xlpm.rowMatch, MATCH( TRIM($D7)&"|"&TRIM($C7), TRIM(INDIRECT(_xlpm.sheet & "!A2:A45")) & "|" & TRIM(INDIRECT(_xlpm.sheet & "!B2:B45")), 0 ), _xlpm.colMatch, MATCH( TRIM(F$3), TRIM(INDIRECT(_xlpm.sheet & "!C1:M1")), 0 ), _xlpm.val, IFERROR(INDEX(INDIRECT(_xlpm.sheet & "!C2:M100"), _xlpm.rowMatch, _xlpm.colMatch), ""), IF(_xlpm.val="", "", _xlpm.val) )} -> 0 | G7: {=_xlfn.LET( _xlpm.sheet, $D$2, _xlpm.rowMatch, MATCH( TRIM($D7)&"|"&TRIM($C7), TRIM(INDIRECT(_xlpm.sheet & "!A2:A45")) & "|" & TRIM(INDIRECT(_xlpm.sheet & "!B2:B45")), 0 ), _xlpm.colMatch, MATCH( TRIM(G$3), TRIM(INDIRECT(_xlpm.sheet & "!C1:M1")), 0 ), _xlpm.val, IFERROR(INDEX(INDIRECT(_xlpm.sheet & "!C2:M100"), _xlpm.rowMatch, _xlpm.colMatch), ""), IF(_xlpm.val="", "", _xlpm.val) )} -> 0 | H7: {=_xlfn.LET( _xlpm.sheet, $D$2, _xlpm.rowMatch, MATCH( TRIM($D7)&"|"&TRIM($C7), TRIM(INDIRECT(_xlpm.sheet & "!A2:A45")) & "|" & TRIM(INDIRECT(_xlpm.sheet & "!B2:B45")), 0 ), _xlpm.colMatch, MATCH( TRIM(H$3), TRIM(INDIRECT(_xlpm.sheet & "!C1:M1")), 0 ), _xlpm.val, IFERROR(INDEX(INDIRECT(_xlpm.sheet & "!C2:M100"), _xlpm.rowMatch, _xlpm.colMatch), ""), IF(_xlpm.val="", "", _xlpm.val) )} -> 0 | I7: {=_xlfn.LET( _xlpm.sheet, $D$2, _xlpm.rowMatch, MATCH( TRIM($D7)&"|"&TRIM($C7), TRIM(INDIRECT(_xlpm.sheet & "!A2:A45")) & "|" & TRIM(INDIRECT(_xlpm.sheet & "!B2:B45")), 0 ), _xlpm.colMatch, MATCH( TRIM(I$3), TRIM(INDIRECT(_xlpm.sheet & "!C1:M1")), 0 ), _xlpm.val, IFERROR(INDEX(INDIRECT(_xlpm.sheet & "!C2:M100"), _xlpm.rowMatch, _xlpm.colMatch), ""), IF(_xlpm.val="", "", _xlpm.val) )} -> 0.8870 | J7: {=_xlfn.LET( _xlpm.sheet, $D$2, _xlpm.rowMatch, MATCH( TRIM($D7)&"|"&TRIM($C7), TRIM(INDIRECT(_xlpm.sheet & "!A2:A45")) & "|" & TRIM(INDIRECT(_xlpm.sheet & "!B2:B45")), 0 ), _xlpm.colMatch, MATCH( TRIM(J$3), TRIM(INDIRECT(_xlpm.sheet & "!C1:M1")), 0 ), _xlpm.val, IFERROR(INDEX(INDIRECT(_xlpm.sheet & "!C2:M100"), _xlpm.rowMatch, _xlpm.colMatch), ""), IF(_xlpm.val="", "", _xlpm.val) )} -> 0.0168 | K7: {=_xlfn.LET( _xlpm.sheet, $D$2, _xlpm.rowMatch, MATCH( TRIM($D7)&"|"&TRIM($C7), TRIM(INDIRECT(_xlpm.sheet & "!A2:A45")) & "|" & TRIM(INDIRECT(_xlpm.sheet & "!B2:B45")), 0 ), _xlpm.colMatch, MATCH( TRIM(K$3), TRIM(INDIRECT(_xlpm.sheet & "!C1:M1")), 0 ), _xlpm.val, IFERROR(INDEX(INDIRECT(_xlpm.sheet & "!C2:M100"), _xlpm.rowMatch, _xlpm.colMatch), ""), IF(_xlpm.val="", "", _xlpm.val) )} -> 0.9985 | L7: {=_xlfn.LET( _xlpm.sheet, $D$2, _xlpm.rowMatch, MATCH( TRIM($D7)&"|"&TRIM($C7), TRIM(INDIRECT(_xlpm.sheet & "!A2:A45")) & "|" & TRIM(INDIRECT(_xlpm.sheet & "!B2:B45")), 0 ), _xlpm.colMatch, MATCH( TRIM(L$3), TRIM(INDIRECT(_xlpm.sheet & "!C1:M1")), 0 ), _xlpm.val, IFERROR(INDEX(INDIRECT(_xlpm.sheet & "!C2:M100"), _xlpm.rowMatch, _xlpm.colMatch), ""), IF(_xlpm.val="", "", _xlpm.val) )} -> 0 | M7: {=_xlfn.LET( _xlpm.sheet, $D$2, _xlpm.rowMatch, MATCH( TRIM($D7)&"|"&TRIM($C7), TRIM(INDIRECT(_xlpm.sheet & "!A2:A45")) & "|" & TRIM(INDIRECT(_xlpm.sheet & "!B2:B45")), 0 ), _xlpm.colMatch, MATCH( TRIM(M$3), TRIM(INDIRECT(_xlpm.sheet & "!C1:M1")), 0 ), _xlpm.val, IFERROR(INDEX(INDIRECT(_xlpm.sheet & "!C2:M100"), _xlpm.rowMatch, _xlpm.colMatch), ""), IF(_xlpm.val="", "", _xlpm.val) )} -> 0 | ... P7: {=_xlfn.LET( _xlpm.sheet, $D$2, _xlpm.rowMatch, MATCH( TRIM($D7)&"|"&TRIM($C7), TRIM(INDIRECT(_xlpm.sheet & "!A2:A45")) & "|" & TRIM(INDIRECT(_xlpm.sheet & "!B2:B45")), 0 ), _xlpm.colMatch, MATCH( TRIM(P$3), TRIM(INDIRECT(_xlpm.sheet & "!C1:M1")), 0 ), _xlpm.val, IFERROR(INDEX(INDIRECT(_xlpm.sheet & "!C2:M100"), _xlpm.rowMatch, _xlpm.colMatch), ""), IF(_xlpm.val="", "", _xlpm.val) )} -> 0.017 | Q7: {=_xlfn.LET( _xlpm.sheet, $D$2, _xlpm.rowMatch, MATCH( TRIM($D7)&"|"&TRIM($C7), TRIM(INDIRECT(_xlpm.sheet & "!A2:A45")) & "|" & TRIM(INDIRECT(_xlpm.sheet & "!B2:B45")), 0 ), _xlpm.colMatch, MATCH( TRIM(Q$3), TRIM(INDIRECT(_xlpm.sheet & "!C1:N1")), 0 ), _xlpm.val, IFERROR(INDEX(INDIRECT(_xlpm.sheet & "!C2:N100"), _xlpm.rowMatch, _xlpm.colMatch), ""), IF(_xlpm.val="", "", _xlpm.val) )} -> 0.9985
B8: {=IFERROR( IF( MOD(ROW()-ROW($B$4), COUNTA(使用方法!$B:$B)) = 0, IF(INDEX(使用方法!$A:$A, INT((ROW()-ROW($B$4))/COUNTA(使用方法!$B:$B))+1) = "", "", INDEX(使用方法!$A:$A, INT((ROW()-ROW($B$4))/COUNTA(使用方法!$B:$B))+1) ), "" ), "")} | C8: =IF(B8<>"", B8, C7) -> LogisticRegression | D8: Ridge (a=1e2) | F8: {=_xlfn.LET( _xlpm.sheet, $D$2, _xlpm.rowMatch, MATCH( TRIM($D8)&"|"&TRIM($C8), TRIM(INDIRECT(_xlpm.sheet & "!A2:A45")) & "|" & TRIM(INDIRECT(_xlpm.sheet & "!B2:B45")), 0 ), _xlpm.colMatch, MATCH( TRIM(F$3), TRIM(INDIRECT(_xlpm.sheet & "!C1:M1")), 0 ), _xlpm.val, IFERROR(INDEX(INDIRECT(_xlpm.sheet & "!C2:M100"), _xlpm.rowMatch, _xlpm.colMatch), ""), IF(_xlpm.val="", "", _xlpm.val) )} -> 0 | G8: {=_xlfn.LET( _xlpm.sheet, $D$2, _xlpm.rowMatch, MATCH( TRIM($D8)&"|"&TRIM($C8), TRIM(INDIRECT(_xlpm.sheet & "!A2:A45")) & "|" & TRIM(INDIRECT(_xlpm.sheet & "!B2:B45")), 0 ), _xlpm.colMatch, MATCH( TRIM(G$3), TRIM(INDIRECT(_xlpm.sheet & "!C1:M1")), 0 ), _xlpm.val, IFERROR(INDEX(INDIRECT(_xlpm.sheet & "!C2:M100"), _xlpm.rowMatch, _xlpm.colMatch), ""), IF(_xlpm.val="", "", _xlpm.val) )} -> 0 | H8: {=_xlfn.LET( _xlpm.sheet, $D$2, _xlpm.rowMatch, MATCH( TRIM($D8)&"|"&TRIM($C8), TRIM(INDIRECT(_xlpm.sheet & "!A2:A45")) & "|" & TRIM(INDIRECT(_xlpm.sheet & "!B2:B45")), 0 ), _xlpm.colMatch, MATCH( TRIM(H$3), TRIM(INDIRECT(_xlpm.sheet & "!C1:M1")), 0 ), _xlpm.val, IFERROR(INDEX(INDIRECT(_xlpm.sheet & "!C2:M100"), _xlpm.rowMatch, _xlpm.colMatch), ""), IF(_xlpm.val="", "", _xlpm.val) )} -> 0 | I8: {=_xlfn.LET( _xlpm.sheet, $D$2, _xlpm.rowMatch, MATCH( TRIM($D8)&"|"&TRIM($C8), TRIM(INDIRECT(_xlpm.sheet & "!A2:A45")) & "|" & TRIM(INDIRECT(_xlpm.sheet & "!B2:B45")), 0 ), _xlpm.colMatch, MATCH( TRIM(I$3), TRIM(INDIRECT(_xlpm.sheet & "!C1:M1")), 0 ), _xlpm.val, IFERROR(INDEX(INDIRECT(_xlpm.sheet & "!C2:M100"), _xlpm.rowMatch, _xlpm.colMatch), ""), IF(_xlpm.val="", "", _xlpm.val) )} -> 0.8650 | J8: {=_xlfn.LET( _xlpm.sheet, $D$2, _xlpm.rowMatch, MATCH( TRIM($D8)&"|"&TRIM($C8), TRIM(INDIRECT(_xlpm.sheet & "!A2:A45")) & "|" & TRIM(INDIRECT(_xlpm.sheet & "!B2:B45")), 0 ), _xlpm.colMatch, MATCH( TRIM(J$3), TRIM(INDIRECT(_xlpm.sheet & "!C1:M1")), 0 ), _xlpm.val, IFERROR(INDEX(INDIRECT(_xlpm.sheet & "!C2:M100"), _xlpm.rowMatch, _xlpm.colMatch), ""), IF(_xlpm.val="", "", _xlpm.val) )} -> 0.0132 | K8: {=_xlfn.LET( _xlpm.sheet, $D$2, _xlpm.rowMatch, MATCH( TRIM($D8)&"|"&TRIM($C8), TRIM(INDIRECT(_xlpm.sheet & "!A2:A45")) & "|" & TRIM(INDIRECT(_xlpm.sheet & "!B2:B45")), 0 ), _xlpm.colMatch, MATCH( TRIM(K$3), TRIM(INDIRECT(_xlpm.sheet & "!C1:M1")), 0 ), _xlpm.val, IFERROR(INDEX(INDIRECT(_xlpm.sheet & "!C2:M100"), _xlpm.rowMatch, _xlpm.colMatch), ""), IF(_xlpm.val="", "", _xlpm.val) )} -> 0.9985 | L8: {=_xlfn.LET( _xlpm.sheet, $D$2, _xlpm.rowMatch, MATCH( TRIM($D8)&"|"&TRIM($C8), TRIM(INDIRECT(_xlpm.sheet & "!A2:A45")) & "|" & TRIM(INDIRECT(_xlpm.sheet & "!B2:B45")), 0 ), _xlpm.colMatch, MATCH( TRIM(L$3), TRIM(INDIRECT(_xlpm.sheet & "!C1:M1")), 0 ), _xlpm.val, IFERROR(INDEX(INDIRECT(_xlpm.sheet & "!C2:M100"), _xlpm.rowMatch, _xlpm.colMatch), ""), IF(_xlpm.val="", "", _xlpm.val) )} -> 0 | M8: {=_xlfn.LET( _xlpm.sheet, $D$2, _xlpm.rowMatch, MATCH( TRIM($D8)&"|"&TRIM($C8), TRIM(INDIRECT(_xlpm.sheet & "!A2:A45")) & "|" & TRIM(INDIRECT(_xlpm.sheet & "!B2:B45")), 0 ), _xlpm.colMatch, MATCH( TRIM(M$3), TRIM(INDIRECT(_xlpm.sheet & "!C1:M1")), 0 ), _xlpm.val, IFERROR(INDEX(INDIRECT(_xlpm.sheet & "!C2:M100"), _xlpm.rowMatch, _xlpm.colMatch), ""), IF(_xlpm.val="", "", _xlpm.val) )} -> 0 | ... P8: {=_xlfn.LET( _xlpm.sheet, $D$2, _xlpm.rowMatch, MATCH( TRIM($D8)&"|"&TRIM($C8), TRIM(INDIRECT(_xlpm.sheet & "!A2:A45")) & "|" & TRIM(INDIRECT(_xlpm.sheet & "!B2:B45")), 0 ), _xlpm.colMatch, MATCH( TRIM(P$3), TRIM(INDIRECT(_xlpm.sheet & "!C1:M1")), 0 ), _xlpm.val, IFERROR(INDEX(INDIRECT(_xlpm.sheet & "!C2:M100"), _xlpm.rowMatch, _xlpm.colMatch), ""), IF(_xlpm.val="", "", _xlpm.val) )} -> 0.0133 | Q8: {=_xlfn.LET( _xlpm.sheet, $D$2, _xlpm.rowMatch, MATCH( TRIM($D8)&"|"&TRIM($C8), TRIM(INDIRECT(_xlpm.sheet & "!A2:A45")) & "|" & TRIM(INDIRECT(_xlpm.sheet & "!B2:B45")), 0 ), _xlpm.colMatch, MATCH( TRIM(Q$3), TRIM(INDIRECT(_xlpm.sheet & "!C1:N1")), 0 ), _xlpm.val, IFERROR(INDEX(INDIRECT(_xlpm.sheet & "!C2:N100"), _xlpm.rowMatch, _xlpm.colMatch), ""), IF(_xlpm.val="", "", _xlpm.val) )} -> 0.9985
B9: {=IFERROR( IF( MOD(ROW()-ROW($B$4), COUNTA(使用方法!$B:$B)) = 0, IF(INDEX(使用方法!$A:$A, INT((ROW()-ROW($B$4))/COUNTA(使用方法!$B:$B))+1) = "", "", INDEX(使用方法!$A:$A, INT((ROW()-ROW($B$4))/COUNTA(使用方法!$B:$B))+1) ), "" ), "")} | C9: =IF(B9<>"", B9, C8) -> LogisticRegression | D9: Ridge (a=1e3) | F9: {=_xlfn.LET( _xlpm.sheet, $D$2, _xlpm.rowMatch, MATCH( TRIM($D9)&"|"&TRIM($C9), TRIM(INDIRECT(_xlpm.sheet & "!A2:A45")) & "|" & TRIM(INDIRECT(_xlpm.sheet & "!B2:B45")), 0 ), _xlpm.colMatch, MATCH( TRIM(F$3), TRIM(INDIRECT(_xlpm.sheet & "!C1:M1")), 0 ), _xlpm.val, IFERROR(INDEX(INDIRECT(_xlpm.sheet & "!C2:M100"), _xlpm.rowMatch, _xlpm.colMatch), ""), IF(_xlpm.val="", "", _xlpm.val) )} -> 0 | G9: {=_xlfn.LET( _xlpm.sheet, $D$2, _xlpm.rowMatch, MATCH( TRIM($D9)&"|"&TRIM($C9), TRIM(INDIRECT(_xlpm.sheet & "!A2:A45")) & "|" & TRIM(INDIRECT(_xlpm.sheet & "!B2:B45")), 0 ), _xlpm.colMatch, MATCH( TRIM(G$3), TRIM(INDIRECT(_xlpm.sheet & "!C1:M1")), 0 ), _xlpm.val, IFERROR(INDEX(INDIRECT(_xlpm.sheet & "!C2:M100"), _xlpm.rowMatch, _xlpm.colMatch), ""), IF(_xlpm.val="", "", _xlpm.val) )} -> 0 | H9: {=_xlfn.LET( _xlpm.sheet, $D$2, _xlpm.rowMatch, MATCH( TRIM($D9)&"|"&TRIM($C9), TRIM(INDIRECT(_xlpm.sheet & "!A2:A45")) & "|" & TRIM(INDIRECT(_xlpm.sheet & "!B2:B45")), 0 ), _xlpm.colMatch, MATCH( TRIM(H$3), TRIM(INDIRECT(_xlpm.sheet & "!C1:M1")), 0 ), _xlpm.val, IFERROR(INDEX(INDIRECT(_xlpm.sheet & "!C2:M100"), _xlpm.rowMatch, _xlpm.colMatch), ""), IF(_xlpm.val="", "", _xlpm.val) )} -> 0 | I9: {=_xlfn.LET( _xlpm.sheet, $D$2, _xlpm.rowMatch, MATCH( TRIM($D9)&"|"&TRIM($C9), TRIM(INDIRECT(_xlpm.sheet & "!A2:A45")) & "|" & TRIM(INDIRECT(_xlpm.sheet & "!B2:B45")), 0 ), _xlpm.colMatch, MATCH( TRIM(I$3), TRIM(INDIRECT(_xlpm.sheet & "!C1:M1")), 0 ), _xlpm.val, IFERROR(INDEX(INDIRECT(_xlpm.sheet & "!C2:M100"), _xlpm.rowMatch, _xlpm.colMatch), ""), IF(_xlpm.val="", "", _xlpm.val) )} -> 0.8650 | J9: {=_xlfn.LET( _xlpm.sheet, $D$2, _xlpm.rowMatch, MATCH( TRIM($D9)&"|"&TRIM($C9), TRIM(INDIRECT(_xlpm.sheet & "!A2:A45")) & "|" & TRIM(INDIRECT(_xlpm.sheet & "!B2:B45")), 0 ), _xlpm.colMatch, MATCH( TRIM(J$3), TRIM(INDIRECT(_xlpm.sheet & "!C1:M1")), 0 ), _xlpm.val, IFERROR(INDEX(INDIRECT(_xlpm.sheet & "!C2:M100"), _xlpm.rowMatch, _xlpm.colMatch), ""), IF(_xlpm.val="", "", _xlpm.val) )} -> 0.0132 | K9: {=_xlfn.LET( _xlpm.sheet, $D$2, _xlpm.rowMatch, MATCH( TRIM($D9)&"|"&TRIM($C9), TRIM(INDIRECT(_xlpm.sheet & "!A2:A45")) & "|" & TRIM(INDIRECT(_xlpm.sheet & "!B2:B45")), 0 ), _xlpm.colMatch, MATCH( TRIM(K$3), TRIM(INDIRECT(_xlpm.sheet & "!C1:M1")), 0 ), _xlpm.val, IFERROR(INDEX(INDIRECT(_xlpm.sheet & "!C2:M100"), _xlpm.rowMatch, _xlpm.colMatch), ""), IF(_xlpm.val="", "", _xlpm.val) )} -> 0.9985 | L9: {=_xlfn.LET( _xlpm.sheet, $D$2, _xlpm.rowMatch, MATCH( TRIM($D9)&"|"&TRIM($C9), TRIM(INDIRECT(_xlpm.sheet & "!A2:A45")) & "|" & TRIM(INDIRECT(_xlpm.sheet & "!B2:B45")), 0 ), _xlpm.colMatch, MATCH( TRIM(L$3), TRIM(INDIRECT(_xlpm.sheet & "!C1:M1")), 0 ), _xlpm.val, IFERROR(INDEX(INDIRECT(_xlpm.sheet & "!C2:M100"), _xlpm.rowMatch, _xlpm.colMatch), ""), IF(_xlpm.val="", "", _xlpm.val) )} -> 0 | M9: {=_xlfn.LET( _xlpm.sheet, $D$2, _xlpm.rowMatch, MATCH( TRIM($D9)&"|"&TRIM($C9), TRIM(INDIRECT(_xlpm.sheet & "!A2:A45")) & "|" & TRIM(INDIRECT(_xlpm.sheet & "!B2:B45")), 0 ), _xlpm.colMatch, MATCH( TRIM(M$3), TRIM(INDIRECT(_xlpm.sheet & "!C1:M1")), 0 ), _xlpm.val, IFERROR(INDEX(INDIRECT(_xlpm.sheet & "!C2:M100"), _xlpm.rowMatch, _xlpm.colMatch), ""), IF(_xlpm.val="", "", _xlpm.val) )} -> 0 | ... P9: {=_xlfn.LET( _xlpm.sheet, $D$2, _xlpm.rowMatch, MATCH( TRIM($D9)&"|"&TRIM($C9), TRIM(INDIRECT(_xlpm.sheet & "!A2:A45")) & "|" & TRIM(INDIRECT(_xlpm.sheet & "!B2:B45")), 0 ), _xlpm.colMatch, MATCH( TRIM(P$3), TRIM(INDIRECT(_xlpm.sheet & "!C1:M1")), 0 ), _xlpm.val, IFERROR(INDEX(INDIRECT(_xlpm.sheet & "!C2:M100"), _xlpm.rowMatch, _xlpm.colMatch), ""), IF(_xlpm.val="", "", _xlpm.val) )} -> 0.0133 | Q9: {=_xlfn.LET( _xlpm.sheet, $D$2, _xlpm.rowMatch, MATCH( TRIM($D9)&"|"&TRIM($C9), TRIM(INDIRECT(_xlpm.sheet & "!A2:A45")) & "|" & TRIM(INDIRECT(_xlpm.sheet & "!B2:B45")), 0 ), _xlpm.colMatch, MATCH( TRIM(Q$3), TRIM(INDIRECT(_xlpm.sheet & "!C1:N1")), 0 ), _xlpm.val, IFERROR(INDEX(INDIRECT(_xlpm.sheet & "!C2:N100"), _xlpm.rowMatch, _xlpm.colMatch), ""), IF(_xlpm.val="", "", _xlpm.val) )} -> 0.9985
B10: {=IFERROR( IF( MOD(ROW()-ROW($B$4), COUNTA(使用方法!$B:$B)) = 0, IF(INDEX(使用方法!$A:$A, INT((ROW()-ROW($B$4))/COUNTA(使用方法!$B:$B))+1) = "", "", INDEX(使用方法!$A:$A, INT((ROW()-ROW($B$4))/COUNTA(使用方法!$B:$B))+1) ), "" ), "")} | C10: =IF(B10<>"", B10, C9) -> LogisticRegression | D10: Ridge (a=1e4) | F10: {=_xlfn.LET( _xlpm.sheet, $D$2, _xlpm.rowMatch, MATCH( TRIM($D10)&"|"&TRIM($C10), TRIM(INDIRECT(_xlpm.sheet & "!A2:A45")) & "|" & TRIM(INDIRECT(_xlpm.sheet & "!B2:B45")), 0 ), _xlpm.colMatch, MATCH( TRIM(F$3), TRIM(INDIRECT(_xlpm.sheet & "!C1:M1")), 0 ), _xlpm.val, IFERROR(INDEX(INDIRECT(_xlpm.sheet & "!C2:M100"), _xlpm.rowMatch, _xlpm.colMatch), ""), IF(_xlpm.val="", "", _xlpm.val) )} -> 0 | G10: {=_xlfn.LET( _xlpm.sheet, $D$2, _xlpm.rowMatch, MATCH( TRIM($D10)&"|"&TRIM($C10), TRIM(INDIRECT(_xlpm.sheet & "!A2:A45")) & "|" & TRIM(INDIRECT(_xlpm.sheet & "!B2:B45")), 0 ), _xlpm.colMatch, MATCH( TRIM(G$3), TRIM(INDIRECT(_xlpm.sheet & "!C1:M1")), 0 ), _xlpm.val, IFERROR(INDEX(INDIRECT(_xlpm.sheet & "!C2:M100"), _xlpm.rowMatch, _xlpm.colMatch), ""), IF(_xlpm.val="", "", _xlpm.val) )} -> 0 | H10: {=_xlfn.LET( _xlpm.sheet, $D$2, _xlpm.rowMatch, MATCH( TRIM($D10)&"|"&TRIM($C10), TRIM(INDIRECT(_xlpm.sheet & "!A2:A45")) & "|" & TRIM(INDIRECT(_xlpm.sheet & "!B2:B45")), 0 ), _xlpm.colMatch, MATCH( TRIM(H$3), TRIM(INDIRECT(_xlpm.sheet & "!C1:M1")), 0 ), _xlpm.val, IFERROR(INDEX(INDIRECT(_xlpm.sheet & "!C2:M100"), _xlpm.rowMatch, _xlpm.colMatch), ""), IF(_xlpm.val="", "", _xlpm.val) )} -> 0 | I10: {=_xlfn.LET( _xlpm.sheet, $D$2, _xlpm.rowMatch, MATCH( TRIM($D10)&"|"&TRIM($C10), TRIM(INDIRECT(_xlpm.sheet & "!A2:A45")) & "|" & TRIM(INDIRECT(_xlpm.sheet & "!B2:B45")), 0 ), _xlpm.colMatch, MATCH( TRIM(I$3), TRIM(INDIRECT(_xlpm.sheet & "!C1:M1")), 0 ), _xlpm.val, IFERROR(INDEX(INDIRECT(_xlpm.sheet & "!C2:M100"), _xlpm.rowMatch, _xlpm.colMatch), ""), IF(_xlpm.val="", "", _xlpm.val) )} -> 0.8897 | J10: {=_xlfn.LET( _xlpm.sheet, $D$2, _xlpm.rowMatch, MATCH( TRIM($D10)&"|"&TRIM($C10), TRIM(INDIRECT(_xlpm.sheet & "!A2:A45")) & "|" & TRIM(INDIRECT(_xlpm.sheet & "!B2:B45")), 0 ), _xlpm.colMatch, MATCH( TRIM(J$3), TRIM(INDIRECT(_xlpm.sheet & "!C1:M1")), 0 ), _xlpm.val, IFERROR(INDEX(INDIRECT(_xlpm.sheet & "!C2:M100"), _xlpm.rowMatch, _xlpm.colMatch), ""), IF(_xlpm.val="", "", _xlpm.val) )} -> 0.0179 | K10: {=_xlfn.LET( _xlpm.sheet, $D$2, _xlpm.rowMatch, MATCH( TRIM($D10)&"|"&TRIM($C10), TRIM(INDIRECT(_xlpm.sheet & "!A2:A45")) & "|" & TRIM(INDIRECT(_xlpm.sheet & "!B2:B45")), 0 ), _xlpm.colMatch, MATCH( TRIM(K$3), TRIM(INDIRECT(_xlpm.sheet & "!C1:M1")), 0 ), _xlpm.val, IFERROR(INDEX(INDIRECT(_xlpm.sheet & "!C2:M100"), _xlpm.rowMatch, _xlpm.colMatch), ""), IF(_xlpm.val="", "", _xlpm.val) )} -> 0.9985 | L10: {=_xlfn.LET( _xlpm.sheet, $D$2, _xlpm.rowMatch, MATCH( TRIM($D10)&"|"&TRIM($C10), TRIM(INDIRECT(_xlpm.sheet & "!A2:A45")) & "|" & TRIM(INDIRECT(_xlpm.sheet & "!B2:B45")), 0 ), _xlpm.colMatch, MATCH( TRIM(L$3), TRIM(INDIRECT(_xlpm.sheet & "!C1:M1")), 0 ), _xlpm.val, IFERROR(INDEX(INDIRECT(_xlpm.sheet & "!C2:M100"), _xlpm.rowMatch, _xlpm.colMatch), ""), IF(_xlpm.val="", "", _xlpm.val) )} -> 0 | M10: {=_xlfn.LET( _xlpm.sheet, $D$2, _xlpm.rowMatch, MATCH( TRIM($D10)&"|"&TRIM($C10), TRIM(INDIRECT(_xlpm.sheet & "!A2:A45")) & "|" & TRIM(INDIRECT(_xlpm.sheet & "!B2:B45")), 0 ), _xlpm.colMatch, MATCH( TRIM(M$3), TRIM(INDIRECT(_xlpm.sheet & "!C1:M1")), 0 ), _xlpm.val, IFERROR(INDEX(INDIRECT(_xlpm.sheet & "!C2:M100"), _xlpm.rowMatch, _xlpm.colMatch), ""), IF(_xlpm.val="", "", _xlpm.val) )} -> 0 | ... P10: {=_xlfn.LET( _xlpm.sheet, $D$2, _xlpm.rowMatch, MATCH( TRIM($D10)&"|"&TRIM($C10), TRIM(INDIRECT(_xlpm.sheet & "!A2:A45")) & "|" & TRIM(INDIRECT(_xlpm.sheet & "!B2:B45")), 0 ), _xlpm.colMatch, MATCH( TRIM(P$3), TRIM(INDIRECT(_xlpm.sheet & "!C1:M1")), 0 ), _xlpm.val, IFERROR(INDEX(INDIRECT(_xlpm.sheet & "!C2:M100"), _xlpm.rowMatch, _xlpm.colMatch), ""), IF(_xlpm.val="", "", _xlpm.val) )} -> 0.0182 | Q10: {=_xlfn.LET( _xlpm.sheet, $D$2, _xlpm.rowMatch, MATCH( TRIM($D10)&"|"&TRIM($C10), TRIM(INDIRECT(_xlpm.sheet & "!A2:A45")) & "|" & TRIM(INDIRECT(_xlpm.sheet & "!B2:B45")), 0 ), _xlpm.colMatch, MATCH( TRIM(Q$3), TRIM(INDIRECT(_xlpm.sheet & "!C1:N1")), 0 ), _xlpm.val, IFERROR(INDEX(INDIRECT(_xlpm.sheet & "!C2:N100"), _xlpm.rowMatch, _xlpm.colMatch), ""), IF(_xlpm.val="", "", _xlpm.val) )} -> 0.9985
B11: {=IFERROR( IF( MOD(ROW()-ROW($B$4), COUNTA(使用方法!$B:$B)) = 0, IF(INDEX(使用方法!$A:$A, INT((ROW()-ROW($B$4))/COUNTA(使用方法!$B:$B))+1) = "", "", INDEX(使用方法!$A:$A, INT((ROW()-ROW($B$4))/COUNTA(使用方法!$B:$B))+1) ), "" ), "")} | C11: =IF(B11<>"", B11, C10) -> LogisticRegression | D11: Ridge (a=1e5) | F11: {=_xlfn.LET( _xlpm.sheet, $D$2, _xlpm.rowMatch, MATCH( TRIM($D11)&"|"&TRIM($C11), TRIM(INDIRECT(_xlpm.sheet & "!A2:A45")) & "|" & TRIM(INDIRECT(_xlpm.sheet & "!B2:B45")), 0 ), _xlpm.colMatch, MATCH( TRIM(F$3), TRIM(INDIRECT(_xlpm.sheet & "!C1:M1")), 0 ), _xlpm.val, IFERROR(INDEX(INDIRECT(_xlpm.sheet & "!C2:M100"), _xlpm.rowMatch, _xlpm.colMatch), ""), IF(_xlpm.val="", "", _xlpm.val) )} -> 0 | G11: {=_xlfn.LET( _xlpm.sheet, $D$2, _xlpm.rowMatch, MATCH( TRIM($D11)&"|"&TRIM($C11), TRIM(INDIRECT(_xlpm.sheet & "!A2:A45")) & "|" & TRIM(INDIRECT(_xlpm.sheet & "!B2:B45")), 0 ), _xlpm.colMatch, MATCH( TRIM(G$3), TRIM(INDIRECT(_xlpm.sheet & "!C1:M1")), 0 ), _xlpm.val, IFERROR(INDEX(INDIRECT(_xlpm.sheet & "!C2:M100"), _xlpm.rowMatch, _xlpm.colMatch), ""), IF(_xlpm.val="", "", _xlpm.val) )} -> 0 | H11: {=_xlfn.LET( _xlpm.sheet, $D$2, _xlpm.rowMatch, MATCH( TRIM($D11)&"|"&TRIM($C11), TRIM(INDIRECT(_xlpm.sheet & "!A2:A45")) & "|" & TRIM(INDIRECT(_xlpm.sheet & "!B2:B45")), 0 ), _xlpm.colMatch, MATCH( TRIM(H$3), TRIM(INDIRECT(_xlpm.sheet & "!C1:M1")), 0 ), _xlpm.val, IFERROR(INDEX(INDIRECT(_xlpm.sheet & "!C2:M100"), _xlpm.rowMatch, _xlpm.colMatch), ""), IF(_xlpm.val="", "", _xlpm.val) )} -> 0 | I11: {=_xlfn.LET( _xlpm.sheet, $D$2, _xlpm.rowMatch, MATCH( TRIM($D11)&"|"&TRIM($C11), TRIM(INDIRECT(_xlpm.sheet & "!A2:A45")) & "|" & TRIM(INDIRECT(_xlpm.sheet & "!B2:B45")), 0 ), _xlpm.colMatch, MATCH( TRIM(I$3), TRIM(INDIRECT(_xlpm.sheet & "!C1:M1")), 0 ), _xlpm.val, IFERROR(INDEX(INDIRECT(_xlpm.sheet & "!C2:M100"), _xlpm.rowMatch, _xlpm.colMatch), ""), IF(_xlpm.val="", "", _xlpm.val) )} -> 0.8893 | J11: {=_xlfn.LET( _xlpm.sheet, $D$2, _xlpm.rowMatch, MATCH( TRIM($D11)&"|"&TRIM($C11), TRIM(INDIRECT(_xlpm.sheet & "!A2:A45")) & "|" & TRIM(INDIRECT(_xlpm.sheet & "!B2:B45")), 0 ), _xlpm.colMatch, MATCH( TRIM(J$3), TRIM(INDIRECT(_xlpm.sheet & "!C1:M1")), 0 ), _xlpm.val, IFERROR(INDEX(INDIRECT(_xlpm.sheet & "!C2:M100"), _xlpm.rowMatch, _xlpm.colMatch), ""), IF(_xlpm.val="", "", _xlpm.val) )} -> 0.0183 | K11: {=_xlfn.LET( _xlpm.sheet, $D$2, _xlpm.rowMatch, MATCH( TRIM($D11)&"|"&TRIM($C11), TRIM(INDIRECT(_xlpm.sheet & "!A2:A45")) & "|" & TRIM(INDIRECT(_xlpm.sheet & "!B2:B45")), 0 ), _xlpm.colMatch, MATCH( TRIM(K$3), TRIM(INDIRECT(_xlpm.sheet & "!C1:M1")), 0 ), _xlpm.val, IFERROR(INDEX(INDIRECT(_xlpm.sheet & "!C2:M100"), _xlpm.rowMatch, _xlpm.colMatch), ""), IF(_xlpm.val="", "", _xlpm.val) )} -> 0.9985 | L11: {=_xlfn.LET( _xlpm.sheet, $D$2, _xlpm.rowMatch, MATCH( TRIM($D11)&"|"&TRIM($C11), TRIM(INDIRECT(_xlpm.sheet & "!A2:A45")) & "|" & TRIM(INDIRECT(_xlpm.sheet & "!B2:B45")), 0 ), _xlpm.colMatch, MATCH( TRIM(L$3), TRIM(INDIRECT(_xlpm.sheet & "!C1:M1")), 0 ), _xlpm.val, IFERROR(INDEX(INDIRECT(_xlpm.sheet & "!C2:M100"), _xlpm.rowMatch, _xlpm.colMatch), ""), IF(_xlpm.val="", "", _xlpm.val) )} -> 0 | M11: {=_xlfn.LET( _xlpm.sheet, $D$2, _xlpm.rowMatch, MATCH( TRIM($D11)&"|"&TRIM($C11), TRIM(INDIRECT(_xlpm.sheet & "!A2:A45")) & "|" & TRIM(INDIRECT(_xlpm.sheet & "!B2:B45")), 0 ), _xlpm.colMatch, MATCH( TRIM(M$3), TRIM(INDIRECT(_xlpm.sheet & "!C1:M1")), 0 ), _xlpm.val, IFERROR(INDEX(INDIRECT(_xlpm.sheet & "!C2:M100"), _xlpm.rowMatch, _xlpm.colMatch), ""), IF(_xlpm.val="", "", _xlpm.val) )} -> 0 | ... P11: {=_xlfn.LET( _xlpm.sheet, $D$2, _xlpm.rowMatch, MATCH( TRIM($D11)&"|"&TRIM($C11), TRIM(INDIRECT(_xlpm.sheet & "!A2:A45")) & "|" & TRIM(INDIRECT(_xlpm.sheet & "!B2:B45")), 0 ), _xlpm.colMatch, MATCH( TRIM(P$3), TRIM(INDIRECT(_xlpm.sheet & "!C1:M1")), 0 ), _xlpm.val, IFERROR(INDEX(INDIRECT(_xlpm.sheet & "!C2:M100"), _xlpm.rowMatch, _xlpm.colMatch), ""), IF(_xlpm.val="", "", _xlpm.val) )} -> 0.0187 | Q11: {=_xlfn.LET( _xlpm.sheet, $D$2, _xlpm.rowMatch, MATCH( TRIM($D11)&"|"&TRIM($C11), TRIM(INDIRECT(_xlpm.sheet & "!A2:A45")) & "|" & TRIM(INDIRECT(_xlpm.sheet & "!B2:B45")), 0 ), _xlpm.colMatch, MATCH( TRIM(Q$3), TRIM(INDIRECT(_xlpm.sheet & "!C1:N1")), 0 ), _xlpm.val, IFERROR(INDEX(INDIRECT(_xlpm.sheet & "!C2:N100"), _xlpm.rowMatch, _xlpm.colMatch), ""), IF(_xlpm.val="", "", _xlpm.val) )} -> 0.9985
B12: {=IFERROR( IF( MOD(ROW()-ROW($B$4), COUNTA(使用方法!$B:$B)) = 0, IF(INDEX(使用方法!$A:$A, INT((ROW()-ROW($B$4))/COUNTA(使用方法!$B:$B))+1) = "", "", INDEX(使用方法!$A:$A, INT((ROW()-ROW($B$4))/COUNTA(使用方法!$B:$B))+1) ), "" ), "")} | C12: =IF(B12<>"", B12, C11) -> LogisticRegression | D12: Ridge (a=1e6) | F12: {=_xlfn.LET( _xlpm.sheet, $D$2, _xlpm.rowMatch, MATCH( TRIM($D12)&"|"&TRIM($C12), TRIM(INDIRECT(_xlpm.sheet & "!A2:A45")) & "|" & TRIM(INDIRECT(_xlpm.sheet & "!B2:B45")), 0 ), _xlpm.colMatch, MATCH( TRIM(F$3), TRIM(INDIRECT(_xlpm.sheet & "!C1:M1")), 0 ), _xlpm.val, IFERROR(INDEX(INDIRECT(_xlpm.sheet & "!C2:M100"), _xlpm.rowMatch, _xlpm.colMatch), ""), IF(_xlpm.val="", "", _xlpm.val) )} -> 0 | G12: {=_xlfn.LET( _xlpm.sheet, $D$2, _xlpm.rowMatch, MATCH( TRIM($D12)&"|"&TRIM($C12), TRIM(INDIRECT(_xlpm.sheet & "!A2:A45")) & "|" & TRIM(INDIRECT(_xlpm.sheet & "!B2:B45")), 0 ), _xlpm.colMatch, MATCH( TRIM(G$3), TRIM(INDIRECT(_xlpm.sheet & "!C1:M1")), 0 ), _xlpm.val, IFERROR(INDEX(INDIRECT(_xlpm.sheet & "!C2:M100"), _xlpm.rowMatch, _xlpm.colMatch), ""), IF(_xlpm.val="", "", _xlpm.val) )} -> 0 | H12: {=_xlfn.LET( _xlpm.sheet, $D$2, _xlpm.rowMatch, MATCH( TRIM($D12)&"|"&TRIM($C12), TRIM(INDIRECT(_xlpm.sheet & "!A2:A45")) & "|" & TRIM(INDIRECT(_xlpm.sheet & "!B2:B45")), 0 ), _xlpm.colMatch, MATCH( TRIM(H$3), TRIM(INDIRECT(_xlpm.sheet & "!C1:M1")), 0 ), _xlpm.val, IFERROR(INDEX(INDIRECT(_xlpm.sheet & "!C2:M100"), _xlpm.rowMatch, _xlpm.colMatch), ""), IF(_xlpm.val="", "", _xlpm.val) )} -> 0 | I12: {=_xlfn.LET( _xlpm.sheet, $D$2, _xlpm.rowMatch, MATCH( TRIM($D12)&"|"&TRIM($C12), TRIM(INDIRECT(_xlpm.sheet & "!A2:A45")) & "|" & TRIM(INDIRECT(_xlpm.sheet & "!B2:B45")), 0 ), _xlpm.colMatch, MATCH( TRIM(I$3), TRIM(INDIRECT(_xlpm.sheet & "!C1:M1")), 0 ), _xlpm.val, IFERROR(INDEX(INDIRECT(_xlpm.sheet & "!C2:M100"), _xlpm.rowMatch, _xlpm.colMatch), ""), IF(_xlpm.val="", "", _xlpm.val) )} -> 0.8767 | J12: {=_xlfn.LET( _xlpm.sheet, $D$2, _xlpm.rowMatch, MATCH( TRIM($D12)&"|"&TRIM($C12), TRIM(INDIRECT(_xlpm.sheet & "!A2:A45")) & "|" & TRIM(INDIRECT(_xlpm.sheet & "!B2:B45")), 0 ), _xlpm.colMatch, MATCH( TRIM(J$3), TRIM(INDIRECT(_xlpm.sheet & "!C1:M1")), 0 ), _xlpm.val, IFERROR(INDEX(INDIRECT(_xlpm.sheet & "!C2:M100"), _xlpm.rowMatch, _xlpm.colMatch), ""), IF(_xlpm.val="", "", _xlpm.val) )} -> 0.0164 | K12: {=_xlfn.LET( _xlpm.sheet, $D$2, _xlpm.rowMatch, MATCH( TRIM($D12)&"|"&TRIM($C12), TRIM(INDIRECT(_xlpm.sheet & "!A2:A45")) & "|" & TRIM(INDIRECT(_xlpm.sheet & "!B2:B45")), 0 ), _xlpm.colMatch, MATCH( TRIM(K$3), TRIM(INDIRECT(_xlpm.sheet & "!C1:M1")), 0 ), _xlpm.val, IFERROR(INDEX(INDIRECT(_xlpm.sheet & "!C2:M100"), _xlpm.rowMatch, _xlpm.colMatch), ""), IF(_xlpm.val="", "", _xlpm.val) )} -> 0.9985 | L12: {=_xlfn.LET( _xlpm.sheet, $D$2, _xlpm.rowMatch, MATCH( TRIM($D12)&"|"&TRIM($C12), TRIM(INDIRECT(_xlpm.sheet & "!A2:A45")) & "|" & TRIM(INDIRECT(_xlpm.sheet & "!B2:B45")), 0 ), _xlpm.colMatch, MATCH( TRIM(L$3), TRIM(INDIRECT(_xlpm.sheet & "!C1:M1")), 0 ), _xlpm.val, IFERROR(INDEX(INDIRECT(_xlpm.sheet & "!C2:M100"), _xlpm.rowMatch, _xlpm.colMatch), ""), IF(_xlpm.val="", "", _xlpm.val) )} -> 0 | M12: {=_xlfn.LET( _xlpm.sheet, $D$2, _xlpm.rowMatch, MATCH( TRIM($D12)&"|"&TRIM($C12), TRIM(INDIRECT(_xlpm.sheet & "!A2:A45")) & "|" & TRIM(INDIRECT(_xlpm.sheet & "!B2:B45")), 0 ), _xlpm.colMatch, MATCH( TRIM(M$3), TRIM(INDIRECT(_xlpm.sheet & "!C1:M1")), 0 ), _xlpm.val, IFERROR(INDEX(INDIRECT(_xlpm.sheet & "!C2:M100"), _xlpm.rowMatch, _xlpm.colMatch), ""), IF(_xlpm.val="", "", _xlpm.val) )} -> 0 | ... P12: {=_xlfn.LET( _xlpm.sheet, $D$2, _xlpm.rowMatch, MATCH( TRIM($D12)&"|"&TRIM($C12), TRIM(INDIRECT(_xlpm.sheet & "!A2:A45")) & "|" & TRIM(INDIRECT(_xlpm.sheet & "!B2:B45")), 0 ), _xlpm.colMatch, MATCH( TRIM(P$3), TRIM(INDIRECT(_xlpm.sheet & "!C1:M1")), 0 ), _xlpm.val, IFERROR(INDEX(INDIRECT(_xlpm.sheet & "!C2:M100"), _xlpm.rowMatch, _xlpm.colMatch), ""), IF(_xlpm.val="", "", _xlpm.val) )} -> 0.0165 | Q12: {=_xlfn.LET( _xlpm.sheet, $D$2, _xlpm.rowMatch, MATCH( TRIM($D12)&"|"&TRIM($C12), TRIM(INDIRECT(_xlpm.sheet & "!A2:A45")) & "|" & TRIM(INDIRECT(_xlpm.sheet & "!B2:B45")), 0 ), _xlpm.colMatch, MATCH( TRIM(Q$3), TRIM(INDIRECT(_xlpm.sheet & "!C1:N1")), 0 ), _xlpm.val, IFERROR(INDEX(INDIRECT(_xlpm.sheet & "!C2:N100"), _xlpm.rowMatch, _xlpm.colMatch), ""), IF(_xlpm.val="", "", _xlpm.val) )} -> 0.9985
B13: {=IFERROR( IF( MOD(ROW()-ROW($B$4), COUNTA(使用方法!$B:$B)) = 0, IF(INDEX(使用方法!$A:$A, INT((ROW()-ROW($B$4))/COUNTA(使用方法!$B:$B))+1) = "", "", INDEX(使用方法!$A:$A, INT((ROW()-ROW($B$4))/COUNTA(使用方法!$B:$B))+1) ), "" ), "")} | C13: =IF(B13<>"", B13, C12) -> LogisticRegression | D13: XGBoost_Top10 | F13: {=_xlfn.LET( _xlpm.sheet, $D$2, _xlpm.rowMatch, MATCH( TRIM($D13)&"|"&TRIM($C13), TRIM(INDIRECT(_xlpm.sheet & "!A2:A45")) & "|" & TRIM(INDIRECT(_xlpm.sheet & "!B2:B45")), 0 ), _xlpm.colMatch, MATCH( TRIM(F$3), TRIM(INDIRECT(_xlpm.sheet & "!C1:M1")), 0 ), _xlpm.val, IFERROR(INDEX(INDIRECT(_xlpm.sheet & "!C2:M100"), _xlpm.rowMatch, _xlpm.colMatch), ""), IF(_xlpm.val="", "", _xlpm.val) )} -> 0 | G13: {=_xlfn.LET( _xlpm.sheet, $D$2, _xlpm.rowMatch, MATCH( TRIM($D13)&"|"&TRIM($C13), TRIM(INDIRECT(_xlpm.sheet & "!A2:A45")) & "|" & TRIM(INDIRECT(_xlpm.sheet & "!B2:B45")), 0 ), _xlpm.colMatch, MATCH( TRIM(G$3), TRIM(INDIRECT(_xlpm.sheet & "!C1:M1")), 0 ), _xlpm.val, IFERROR(INDEX(INDIRECT(_xlpm.sheet & "!C2:M100"), _xlpm.rowMatch, _xlpm.colMatch), ""), IF(_xlpm.val="", "", _xlpm.val) )} -> 0 | H13: {=_xlfn.LET( _xlpm.sheet, $D$2, _xlpm.rowMatch, MATCH( TRIM($D13)&"|"&TRIM($C13), TRIM(INDIRECT(_xlpm.sheet & "!A2:A45")) & "|" & TRIM(INDIRECT(_xlpm.sheet & "!B2:B45")), 0 ), _xlpm.colMatch, MATCH( TRIM(H$3), TRIM(INDIRECT(_xlpm.sheet & "!C1:M1")), 0 ), _xlpm.val, IFERROR(INDEX(INDIRECT(_xlpm.sheet & "!C2:M100"), _xlpm.rowMatch, _xlpm.colMatch), ""), IF(_xlpm.val="", "", _xlpm.val) )} -> 0 | I13: {=_xlfn.LET( _xlpm.sheet, $D$2, _xlpm.rowMatch, MATCH( TRIM($D13)&"|"&TRIM($C13), TRIM(INDIRECT(_xlpm.sheet & "!A2:A45")) & "|" & TRIM(INDIRECT(_xlpm.sheet & "!B2:B45")), 0 ), _xlpm.colMatch, MATCH( TRIM(I$3), TRIM(INDIRECT(_xlpm.sheet & "!C1:M1")), 0 ), _xlpm.val, IFERROR(INDEX(INDIRECT(_xlpm.sheet & "!C2:M100"), _xlpm.rowMatch, _xlpm.colMatch), ""), IF(_xlpm.val="", "", _xlpm.val) )} -> 0.8763 | J13: {=_xlfn.LET( _xlpm.sheet, $D$2, _xlpm.rowMatch, MATCH( TRIM($D13)&"|"&TRIM($C13), TRIM(INDIRECT(_xlpm.sheet & "!A2:A45")) & "|" & TRIM(INDIRECT(_xlpm.sheet & "!B2:B45")), 0 ), _xlpm.colMatch, MATCH( TRIM(J$3), TRIM(INDIRECT(_xlpm.sheet & "!C1:M1")), 0 ), _xlpm.val, IFERROR(INDEX(INDIRECT(_xlpm.sheet & "!C2:M100"), _xlpm.rowMatch, _xlpm.colMatch), ""), IF(_xlpm.val="", "", _xlpm.val) )} -> 0.0081 | K13: {=_xlfn.LET( _xlpm.sheet, $D$2, _xlpm.rowMatch, MATCH( TRIM($D13)&"|"&TRIM($C13), TRIM(INDIRECT(_xlpm.sheet & "!A2:A45")) & "|" & TRIM(INDIRECT(_xlpm.sheet & "!B2:B45")), 0 ), _xlpm.colMatch, MATCH( TRIM(K$3), TRIM(INDIRECT(_xlpm.sheet & "!C1:M1")), 0 ), _xlpm.val, IFERROR(INDEX(INDIRECT(_xlpm.sheet & "!C2:M100"), _xlpm.rowMatch, _xlpm.colMatch), ""), IF(_xlpm.val="", "", _xlpm.val) )} -> 0.9985 | L13: {=_xlfn.LET( _xlpm.sheet, $D$2, _xlpm.rowMatch, MATCH( TRIM($D13)&"|"&TRIM($C13), TRIM(INDIRECT(_xlpm.sheet & "!A2:A45")) & "|" & TRIM(INDIRECT(_xlpm.sheet & "!B2:B45")), 0 ), _xlpm.colMatch, MATCH( TRIM(L$3), TRIM(INDIRECT(_xlpm.sheet & "!C1:M1")), 0 ), _xlpm.val, IFERROR(INDEX(INDIRECT(_xlpm.sheet & "!C2:M100"), _xlpm.rowMatch, _xlpm.colMatch), ""), IF(_xlpm.val="", "", _xlpm.val) )} -> 0 | M13: {=_xlfn.LET( _xlpm.sheet, $D$2, _xlpm.rowMatch, MATCH( TRIM($D13)&"|"&TRIM($C13), TRIM(INDIRECT(_xlpm.sheet & "!A2:A45")) & "|" & TRIM(INDIRECT(_xlpm.sheet & "!B2:B45")), 0 ), _xlpm.colMatch, MATCH( TRIM(M$3), TRIM(INDIRECT(_xlpm.sheet & "!C1:M1")), 0 ), _xlpm.val, IFERROR(INDEX(INDIRECT(_xlpm.sheet & "!C2:M100"), _xlpm.rowMatch, _xlpm.colMatch), ""), IF(_xlpm.val="", "", _xlpm.val) )} -> 0 | ... P13: {=_xlfn.LET( _xlpm.sheet, $D$2, _xlpm.rowMatch, MATCH( TRIM($D13)&"|"&TRIM($C13), TRIM(INDIRECT(_xlpm.sheet & "!A2:A45")) & "|" & TRIM(INDIRECT(_xlpm.sheet & "!B2:B45")), 0 ), _xlpm.colMatch, MATCH( TRIM(P$3), TRIM(INDIRECT(_xlpm.sheet & "!C1:M1")), 0 ), _xlpm.val, IFERROR(INDEX(INDIRECT(_xlpm.sheet & "!C2:M100"), _xlpm.rowMatch, _xlpm.colMatch), ""), IF(_xlpm.val="", "", _xlpm.val) )} -> 0.0081 | Q13: {=_xlfn.LET( _xlpm.sheet, $D$2, _xlpm.rowMatch, MATCH( TRIM($D13)&"|"&TRIM($C13), TRIM(INDIRECT(_xlpm.sheet & "!A2:A45")) & "|" & TRIM(INDIRECT(_xlpm.sheet & "!B2:B45")), 0 ), _xlpm.colMatch, MATCH( TRIM(Q$3), TRIM(INDIRECT(_xlpm.sheet & "!C1:N1")), 0 ), _xlpm.val, IFERROR(INDEX(INDIRECT(_xlpm.sheet & "!C2:N100"), _xlpm.rowMatch, _xlpm.colMatch), ""), IF(_xlpm.val="", "", _xlpm.val) )} -> 0.9985
B14: {=IFERROR( IF( MOD(ROW()-ROW($B$4), COUNTA(使用方法!$B:$B)) = 0, IF(INDEX(使用方法!$A:$A, INT((ROW()-ROW($B$4))/COUNTA(使用方法!$B:$B))+1) = "", "", INDEX(使用方法!$A:$A, INT((ROW()-ROW($B$4))/COUNTA(使用方法!$B:$B))+1) ), "" ), "")} -> LDA | C14: =IF(B14<>"", B14, C13) -> LDA | D14: Full_Set_Baseline | F14: {=_xlfn.LET( _xlpm.sheet, $D$2, _xlpm.rowMatch, MATCH( TRIM($D14)&"|"&TRIM($C14), TRIM(INDIRECT(_xlpm.sheet & "!A2:A45")) & "|" & TRIM(INDIRECT(_xlpm.sheet & "!B2:B45")), 0 ), _xlpm.colMatch, MATCH( TRIM(F$3), TRIM(INDIRECT(_xlpm.sheet & "!C1:M1")), 0 ), _xlpm.val, IFERROR(INDEX(INDIRECT(_xlpm.sheet & "!C2:M100"), _xlpm.rowMatch, _xlpm.colMatch), ""), IF(_xlpm.val="", "", _xlpm.val) )} | G14: {=_xlfn.LET( _xlpm.sheet, $D$2, _xlpm.rowMatch, MATCH( TRIM($D14)&"|"&TRIM($C14), TRIM(INDIRECT(_xlpm.sheet & "!A2:A45")) & "|" & TRIM(INDIRECT(_xlpm.sheet & "!B2:B45")), 0 ), _xlpm.colMatch, MATCH( TRIM(G$3), TRIM(INDIRECT(_xlpm.sheet & "!C1:M1")), 0 ), _xlpm.val, IFERROR(INDEX(INDIRECT(_xlpm.sheet & "!C2:M100"), _xlpm.rowMatch, _xlpm.colMatch), ""), IF(_xlpm.val="", "", _xlpm.val) )} | H14: {=_xlfn.LET( _xlpm.sheet, $D$2, _xlpm.rowMatch, MATCH( TRIM($D14)&"|"&TRIM($C14), TRIM(INDIRECT(_xlpm.sheet & "!A2:A45")) & "|" & TRIM(INDIRECT(_xlpm.sheet & "!B2:B45")), 0 ), _xlpm.colMatch, MATCH( TRIM(H$3), TRIM(INDIRECT(_xlpm.sheet & "!C1:M1")), 0 ), _xlpm.val, IFERROR(INDEX(INDIRECT(_xlpm.sheet & "!C2:M100"), _xlpm.rowMatch, _xlpm.colMatch), ""), IF(_xlpm.val="", "", _xlpm.val) )} | I14: {=_xlfn.LET( _xlpm.sheet, $D$2, _xlpm.rowMatch, MATCH( TRIM($D14)&"|"&TRIM($C14), TRIM(INDIRECT(_xlpm.sheet & "!A2:A45")) & "|" & TRIM(INDIRECT(_xlpm.sheet & "!B2:B45")), 0 ), _xlpm.colMatch, MATCH( TRIM(I$3), TRIM(INDIRECT(_xlpm.sheet & "!C1:M1")), 0 ), _xlpm.val, IFERROR(INDEX(INDIRECT(_xlpm.sheet & "!C2:M100"), _xlpm.rowMatch, _xlpm.colMatch), ""), IF(_xlpm.val="", "", _xlpm.val) )} | J14: {=_xlfn.LET( _xlpm.sheet, $D$2, _xlpm.rowMatch, MATCH( TRIM($D14)&"|"&TRIM($C14), TRIM(INDIRECT(_xlpm.sheet & "!A2:A45")) & "|" & TRIM(INDIRECT(_xlpm.sheet & "!B2:B45")), 0 ), _xlpm.colMatch, MATCH( TRIM(J$3), TRIM(INDIRECT(_xlpm.sheet & "!C1:M1")), 0 ), _xlpm.val, IFERROR(INDEX(INDIRECT(_xlpm.sheet & "!C2:M100"), _xlpm.rowMatch, _xlpm.colMatch), ""), IF(_xlpm.val="", "", _xlpm.val) )} | K14: {=_xlfn.LET( _xlpm.sheet, $D$2, _xlpm.rowMatch, MATCH( TRIM($D14)&"|"&TRIM($C14), TRIM(INDIRECT(_xlpm.sheet & "!A2:A45")) & "|" & TRIM(INDIRECT(_xlpm.sheet & "!B2:B45")), 0 ), _xlpm.colMatch, MATCH( TRIM(K$3), TRIM(INDIRECT(_xlpm.sheet & "!C1:M1")), 0 ), _xlpm.val, IFERROR(INDEX(INDIRECT(_xlpm.sheet & "!C2:M100"), _xlpm.rowMatch, _xlpm.colMatch), ""), IF(_xlpm.val="", "", _xlpm.val) )} | L14: {=_xlfn.LET( _xlpm.sheet, $D$2, _xlpm.rowMatch, MATCH( TRIM($D14)&"|"&TRIM($C14), TRIM(INDIRECT(_xlpm.sheet & "!A2:A45")) & "|" & TRIM(INDIRECT(_xlpm.sheet & "!B2:B45")), 0 ), _xlpm.colMatch, MATCH( TRIM(L$3), TRIM(INDIRECT(_xlpm.sheet & "!C1:M1")), 0 ), _xlpm.val, IFERROR(INDEX(INDIRECT(_xlpm.sheet & "!C2:M100"), _xlpm.rowMatch, _xlpm.colMatch), ""), IF(_xlpm.val="", "", _xlpm.val) )} | M14: {=_xlfn.LET( _xlpm.sheet, $D$2, _xlpm.rowMatch, MATCH( TRIM($D14)&"|"&TRIM($C14), TRIM(INDIRECT(_xlpm.sheet & "!A2:A45")) & "|" & TRIM(INDIRECT(_xlpm.sheet & "!B2:B45")), 0 ), _xlpm.colMatch, MATCH( TRIM(M$3), TRIM(INDIRECT(_xlpm.sheet & "!C1:M1")), 0 ), _xlpm.val, IFERROR(INDEX(INDIRECT(_xlpm.sheet & "!C2:M100"), _xlpm.rowMatch, _xlpm.colMatch), ""), IF(_xlpm.val="", "", _xlpm.val) )} | ... P14: {=_xlfn.LET( _xlpm.sheet, $D$2, _xlpm.rowMatch, MATCH( TRIM($D14)&"|"&TRIM($C14), TRIM(INDIRECT(_xlpm.sheet & "!A2:A45")) & "|" & TRIM(INDIRECT(_xlpm.sheet & "!B2:B45")), 0 ), _xlpm.colMatch, MATCH( TRIM(P$3), TRIM(INDIRECT(_xlpm.sheet & "!C1:M1")), 0 ), _xlpm.val, IFERROR(INDEX(INDIRECT(_xlpm.sheet & "!C2:M100"), _xlpm.rowMatch, _xlpm.colMatch), ""), IF(_xlpm.val="", "", _xlpm.val) )} | Q14: {=_xlfn.LET( _xlpm.sheet, $D$2, _xlpm.rowMatch, MATCH( TRIM($D14)&"|"&TRIM($C14), TRIM(INDIRECT(_xlpm.sheet & "!A2:A45")) & "|" & TRIM(INDIRECT(_xlpm.sheet & "!B2:B45")), 0 ), _xlpm.colMatch, MATCH( TRIM(Q$3), TRIM(INDIRECT(_xlpm.sheet & "!C1:N1")), 0 ), _xlpm.val, IFERROR(INDEX(INDIRECT(_xlpm.sheet & "!C2:N100"), _xlpm.rowMatch, _xlpm.colMatch), ""), IF(_xlpm.val="", "", _xlpm.val) )}
B15: {=IFERROR( IF( MOD(ROW()-ROW($B$4), COUNTA(使用方法!$B:$B)) = 0, IF(INDEX(使用方法!$A:$A, INT((ROW()-ROW($B$4))/COUNTA(使用方法!$B:$B))+1) = "", "", INDEX(使用方法!$A:$A, INT((ROW()-ROW($B$4))/COUNTA(使用方法!$B:$B))+1) ), "" ), "")} | C15: =IF(B15<>"", B15, C14) -> LDA | D15: Lasso (a=1e-4) | F15: {=_xlfn.LET( _xlpm.sheet, $D$2, _xlpm.rowMatch, MATCH( TRIM($D15)&"|"&TRIM($C15), TRIM(INDIRECT(_xlpm.sheet & "!A2:A45")) & "|" & TRIM(INDIRECT(_xlpm.sheet & "!B2:B45")), 0 ), _xlpm.colMatch, MATCH( TRIM(F$3), TRIM(INDIRECT(_xlpm.sheet & "!C1:M1")), 0 ), _xlpm.val, IFERROR(INDEX(INDIRECT(_xlpm.sheet & "!C2:M100"), _xlpm.rowMatch, _xlpm.colMatch), ""), IF(_xlpm.val="", "", _xlpm.val) )} -> 0 | G15: {=_xlfn.LET( _xlpm.sheet, $D$2, _xlpm.rowMatch, MATCH( TRIM($D15)&"|"&TRIM($C15), TRIM(INDIRECT(_xlpm.sheet & "!A2:A45")) & "|" & TRIM(INDIRECT(_xlpm.sheet & "!B2:B45")), 0 ), _xlpm.colMatch, MATCH( TRIM(G$3), TRIM(INDIRECT(_xlpm.sheet & "!C1:M1")), 0 ), _xlpm.val, IFERROR(INDEX(INDIRECT(_xlpm.sheet & "!C2:M100"), _xlpm.rowMatch, _xlpm.colMatch), ""), IF(_xlpm.val="", "", _xlpm.val) )} -> 0 | H15: {=_xlfn.LET( _xlpm.sheet, $D$2, _xlpm.rowMatch, MATCH( TRIM($D15)&"|"&TRIM($C15), TRIM(INDIRECT(_xlpm.sheet & "!A2:A45")) & "|" & TRIM(INDIRECT(_xlpm.sheet & "!B2:B45")), 0 ), _xlpm.colMatch, MATCH( TRIM(H$3), TRIM(INDIRECT(_xlpm.sheet & "!C1:M1")), 0 ), _xlpm.val, IFERROR(INDEX(INDIRECT(_xlpm.sheet & "!C2:M100"), _xlpm.rowMatch, _xlpm.colMatch), ""), IF(_xlpm.val="", "", _xlpm.val) )} -> 0 | I15: {=_xlfn.LET( _xlpm.sheet, $D$2, _xlpm.rowMatch, MATCH( TRIM($D15)&"|"&TRIM($C15), TRIM(INDIRECT(_xlpm.sheet & "!A2:A45")) & "|" & TRIM(INDIRECT(_xlpm.sheet & "!B2:B45")), 0 ), _xlpm.colMatch, MATCH( TRIM(I$3), TRIM(INDIRECT(_xlpm.sheet & "!C1:M1")), 0 ), _xlpm.val, IFERROR(INDEX(INDIRECT(_xlpm.sheet & "!C2:M100"), _xlpm.rowMatch, _xlpm.colMatch), ""), IF(_xlpm.val="", "", _xlpm.val) )} -> 0.8682 | J15: {=_xlfn.LET( _xlpm.sheet, $D$2, _xlpm.rowMatch, MATCH( TRIM($D15)&"|"&TRIM($C15), TRIM(INDIRECT(_xlpm.sheet & "!A2:A45")) & "|" & TRIM(INDIRECT(_xlpm.sheet & "!B2:B45")), 0 ), _xlpm.colMatch, MATCH( TRIM(J$3), TRIM(INDIRECT(_xlpm.sheet & "!C1:M1")), 0 ), _xlpm.val, IFERROR(INDEX(INDIRECT(_xlpm.sheet & "!C2:M100"), _xlpm.rowMatch, _xlpm.colMatch), ""), IF(_xlpm.val="", "", _xlpm.val) )} -> 0.0129 | K15: {=_xlfn.LET( _xlpm.sheet, $D$2, _xlpm.rowMatch, MATCH( TRIM($D15)&"|"&TRIM($C15), TRIM(INDIRECT(_xlpm.sheet & "!A2:A45")) & "|" & TRIM(INDIRECT(_xlpm.sheet & "!B2:B45")), 0 ), _xlpm.colMatch, MATCH( TRIM(K$3), TRIM(INDIRECT(_xlpm.sheet & "!C1:M1")), 0 ), _xlpm.val, IFERROR(INDEX(INDIRECT(_xlpm.sheet & "!C2:M100"), _xlpm.rowMatch, _xlpm.colMatch), ""), IF(_xlpm.val="", "", _xlpm.val) )} -> 0.9985 | L15: {=_xlfn.LET( _xlpm.sheet, $D$2, _xlpm.rowMatch, MATCH( TRIM($D15)&"|"&TRIM($C15), TRIM(INDIRECT(_xlpm.sheet & "!A2:A45")) & "|" & TRIM(INDIRECT(_xlpm.sheet & "!B2:B45")), 0 ), _xlpm.colMatch, MATCH( TRIM(L$3), TRIM(INDIRECT(_xlpm.sheet & "!C1:M1")), 0 ), _xlpm.val, IFERROR(INDEX(INDIRECT(_xlpm.sheet & "!C2:M100"), _xlpm.rowMatch, _xlpm.colMatch), ""), IF(_xlpm.val="", "", _xlpm.val) )} -> 0 | M15: {=_xlfn.LET( _xlpm.sheet, $D$2, _xlpm.rowMatch, MATCH( TRIM($D15)&"|"&TRIM($C15), TRIM(INDIRECT(_xlpm.sheet & "!A2:A45")) & "|" & TRIM(INDIRECT(_xlpm.sheet & "!B2:B45")), 0 ), _xlpm.colMatch, MATCH( TRIM(M$3), TRIM(INDIRECT(_xlpm.sheet & "!C1:M1")), 0 ), _xlpm.val, IFERROR(INDEX(INDIRECT(_xlpm.sheet & "!C2:M100"), _xlpm.rowMatch, _xlpm.colMatch), ""), IF(_xlpm.val="", "", _xlpm.val) )} -> 0 | ... P15: {=_xlfn.LET( _xlpm.sheet, $D$2, _xlpm.rowMatch, MATCH( TRIM($D15)&"|"&TRIM($C15), TRIM(INDIRECT(_xlpm.sheet & "!A2:A45")) & "|" & TRIM(INDIRECT(_xlpm.sheet & "!B2:B45")), 0 ), _xlpm.colMatch, MATCH( TRIM(P$3), TRIM(INDIRECT(_xlpm.sheet & "!C1:M1")), 0 ), _xlpm.val, IFERROR(INDEX(INDIRECT(_xlpm.sheet & "!C2:M100"), _xlpm.rowMatch, _xlpm.colMatch), ""), IF(_xlpm.val="", "", _xlpm.val) )} -> 0.0133 | Q15: {=_xlfn.LET( _xlpm.sheet, $D$2, _xlpm.rowMatch, MATCH( TRIM($D15)&"|"&TRIM($C15), TRIM(INDIRECT(_xlpm.sheet & "!A2:A45")) & "|" & TRIM(INDIRECT(_xlpm.sheet & "!B2:B45")), 0 ), _xlpm.colMatch, MATCH( TRIM(Q$3), TRIM(INDIRECT(_xlpm.sheet & "!C1:N1")), 0 ), _xlpm.val, IFERROR(INDEX(INDIRECT(_xlpm.sheet & "!C2:N100"), _xlpm.rowMatch, _xlpm.colMatch), ""), IF(_xlpm.val="", "", _xlpm.val) )} -> 0.9985
B16: {=IFERROR( IF( MOD(ROW()-ROW($B$4), COUNTA(使用方法!$B:$B)) = 0, IF(INDEX(使用方法!$A:$A, INT((ROW()-ROW($B$4))/COUNTA(使用方法!$B:$B))+1) = "", "", INDEX(使用方法!$A:$A, INT((ROW()-ROW($B$4))/COUNTA(使用方法!$B:$B))+1) ), "" ), "")} | C16: =IF(B16<>"", B16, C15) -> LDA | D16: Lasso (a=1e-5) | F16: {=_xlfn.LET( _xlpm.sheet, $D$2, _xlpm.rowMatch, MATCH( TRIM($D16)&"|"&TRIM($C16), TRIM(INDIRECT(_xlpm.sheet & "!A2:A45")) & "|" & TRIM(INDIRECT(_xlpm.sheet & "!B2:B45")), 0 ), _xlpm.colMatch, MATCH( TRIM(F$3), TRIM(INDIRECT(_xlpm.sheet & "!C1:M1")), 0 ), _xlpm.val, IFERROR(INDEX(INDIRECT(_xlpm.sheet & "!C2:M100"), _xlpm.rowMatch, _xlpm.colMatch), ""), IF(_xlpm.val="", "", _xlpm.val) )} -> 0.0438 | G16: {=_xlfn.LET( _xlpm.sheet, $D$2, _xlpm.rowMatch, MATCH( TRIM($D16)&"|"&TRIM($C16), TRIM(INDIRECT(_xlpm.sheet & "!A2:A45")) & "|" & TRIM(INDIRECT(_xlpm.sheet & "!B2:B45")), 0 ), _xlpm.colMatch, MATCH( TRIM(G$3), TRIM(INDIRECT(_xlpm.sheet & "!C1:M1")), 0 ), _xlpm.val, IFERROR(INDEX(INDIRECT(_xlpm.sheet & "!C2:M100"), _xlpm.rowMatch, _xlpm.colMatch), ""), IF(_xlpm.val="", "", _xlpm.val) )} -> 0.1278 | H16: {=_xlfn.LET( _xlpm.sheet, $D$2, _xlpm.rowMatch, MATCH( TRIM($D16)&"|"&TRIM($C16), TRIM(INDIRECT(_xlpm.sheet & "!A2:A45")) & "|" & TRIM(INDIRECT(_xlpm.sheet & "!B2:B45")), 0 ), _xlpm.colMatch, MATCH( TRIM(H$3), TRIM(INDIRECT(_xlpm.sheet & "!C1:M1")), 0 ), _xlpm.val, IFERROR(INDEX(INDIRECT(_xlpm.sheet & "!C2:M100"), _xlpm.rowMatch, _xlpm.colMatch), ""), IF(_xlpm.val="", "", _xlpm.val) )} -> 0.0652 | I16: {=_xlfn.LET( _xlpm.sheet, $D$2, _xlpm.rowMatch, MATCH( TRIM($D16)&"|"&TRIM($C16), TRIM(INDIRECT(_xlpm.sheet & "!A2:A45")) & "|" & TRIM(INDIRECT(_xlpm.sheet & "!B2:B45")), 0 ), _xlpm.colMatch, MATCH( TRIM(I$3), TRIM(INDIRECT(_xlpm.sheet & "!C1:M1")), 0 ), _xlpm.val, IFERROR(INDEX(INDIRECT(_xlpm.sheet & "!C2:M100"), _xlpm.rowMatch, _xlpm.colMatch), ""), IF(_xlpm.val="", "", _xlpm.val) )} -> 0.8706 | J16: {=_xlfn.LET( _xlpm.sheet, $D$2, _xlpm.rowMatch, MATCH( TRIM($D16)&"|"&TRIM($C16), TRIM(INDIRECT(_xlpm.sheet & "!A2:A45")) & "|" & TRIM(INDIRECT(_xlpm.sheet & "!B2:B45")), 0 ), _xlpm.colMatch, MATCH( TRIM(J$3), TRIM(INDIRECT(_xlpm.sheet & "!C1:M1")), 0 ), _xlpm.val, IFERROR(INDEX(INDIRECT(_xlpm.sheet & "!C2:M100"), _xlpm.rowMatch, _xlpm.colMatch), ""), IF(_xlpm.val="", "", _xlpm.val) )} -> 0.0247 | K16: {=_xlfn.LET( _xlpm.sheet, $D$2, _xlpm.rowMatch, MATCH( TRIM($D16)&"|"&TRIM($C16), TRIM(INDIRECT(_xlpm.sheet & "!A2:A45")) & "|" & TRIM(INDIRECT(_xlpm.sheet & "!B2:B45")), 0 ), _xlpm.colMatch, MATCH( TRIM(K$3), TRIM(INDIRECT(_xlpm.sheet & "!C1:M1")), 0 ), _xlpm.val, IFERROR(INDEX(INDIRECT(_xlpm.sheet & "!C2:M100"), _xlpm.rowMatch, _xlpm.colMatch), ""), IF(_xlpm.val="", "", _xlpm.val) )} -> 0.9945 | L16: {=_xlfn.LET( _xlpm.sheet, $D$2, _xlpm.rowMatch, MATCH( TRIM($D16)&"|"&TRIM($C16), TRIM(INDIRECT(_xlpm.sheet & "!A2:A45")) & "|" & TRIM(INDIRECT(_xlpm.sheet & "!B2:B45")), 0 ), _xlpm.colMatch, MATCH( TRIM(L$3), TRIM(INDIRECT(_xlpm.sheet & "!C1:M1")), 0 ), _xlpm.val, IFERROR(INDEX(INDIRECT(_xlpm.sheet & "!C2:M100"), _xlpm.rowMatch, _xlpm.colMatch), ""), IF(_xlpm.val="", "", _xlpm.val) )} -> 0.0427 | M16: {=_xlfn.LET( _xlpm.sheet, $D$2, _xlpm.rowMatch, MATCH( TRIM($D16)&"|"&TRIM($C16), TRIM(INDIRECT(_xlpm.sheet & "!A2:A45")) & "|" & TRIM(INDIRECT(_xlpm.sheet & "!B2:B45")), 0 ), _xlpm.colMatch, MATCH( TRIM(M$3), TRIM(INDIRECT(_xlpm.sheet & "!C1:M1")), 0 ), _xlpm.val, IFERROR(INDEX(INDIRECT(_xlpm.sheet & "!C2:M100"), _xlpm.rowMatch, _xlpm.colMatch), ""), IF(_xlpm.val="", "", _xlpm.val) )} -> 0.124 | ... P16: {=_xlfn.LET( _xlpm.sheet, $D$2, _xlpm.rowMatch, MATCH( TRIM($D16)&"|"&TRIM($C16), TRIM(INDIRECT(_xlpm.sheet & "!A2:A45")) & "|" & TRIM(INDIRECT(_xlpm.sheet & "!B2:B45")), 0 ), _xlpm.colMatch, MATCH( TRIM(P$3), TRIM(INDIRECT(_xlpm.sheet & "!C1:M1")), 0 ), _xlpm.val, IFERROR(INDEX(INDIRECT(_xlpm.sheet & "!C2:M100"), _xlpm.rowMatch, _xlpm.colMatch), ""), IF(_xlpm.val="", "", _xlpm.val) )} -> 0.0226 | Q16: {=_xlfn.LET( _xlpm.sheet, $D$2, _xlpm.rowMatch, MATCH( TRIM($D16)&"|"&TRIM($C16), TRIM(INDIRECT(_xlpm.sheet & "!A2:A45")) & "|" & TRIM(INDIRECT(_xlpm.sheet & "!B2:B45")), 0 ), _xlpm.colMatch, MATCH( TRIM(Q$3), TRIM(INDIRECT(_xlpm.sheet & "!C1:N1")), 0 ), _xlpm.val, IFERROR(INDEX(INDIRECT(_xlpm.sheet & "!C2:N100"), _xlpm.rowMatch, _xlpm.colMatch), ""), IF(_xlpm.val="", "", _xlpm.val) )} -> 0.9945
